Workbook
Name SegmentaciónDeDatos_CANAL: #N/A
Name SegmentaciónDeDatos_DESTINO: #N/A
Name SegmentaciónDeDatos_DESTINO1: #N/A
Name SegmentaciónDeDatos_DESTINO2: #N/A
Name SegmentaciónDeDatos_DESTINO3: #N/A
Name SegmentaciónDeDatos_Edad1: #N/A
Name SegmentaciónDeDatos_GRUPO1: #N/A
Name SegmentaciónDeDatos_INVENTARIO: #N/A
Name SegmentaciónDeDatos_TIPO: #N/A
Name SegmentaciónDeDatos_TIPO_2: #N/A
Name SegmentaciónDeDatos_TIPO_DE_HUEVO: #N/A
Name SegmentaciónDeDatos_TIPO_DE_HUEVO1: #N/A
Name SegmentaciónDeDatos_TIPO_DE_HUEVO2: #N/A
Name SegmentaciónDeDatos_TIPO_HUEVO: #N/A
Name SegmentaciónDeDatos_tipo1: #N/A
Name SegmentaciónDeDatos_ZONA1: #N/A

Sheet Detalle1
A1: Detalles para Cantidades - CANAL: 0
A3: articulo | B3: descripcion_articulo | C3: id_unidad | D3: cantidad | E3: por_dsto | F3: ind_iva_venta | G3: iva_ventas | H3: por_iva | I3: precio_unitario | J3: codigo_linea | K3: descripcion_linea | L3: costo_promedio | M3: fecha | N3: codigo_plu | O3: descripcion | P3: cod_barras1 | Q3: id_bodega | R3: num_piezas | S3: id_item_bodega | T3: DESTINO | U3: GRUPO | V3: TIPO DE HUEVO | W3: TIPO DE HUEVO 2 | X3: ZONA | Y3: P | Z3: MAY | AA3: GRUPO 2 | AB3: CANAL
A4: 112207 | B4: HUEVO XL X 15 PET | C4: UN | D4: 360 | F4: S | G4: IV82 | J4: HU | K4: HUEVO COMERCIAL | L4: 599.68 | M4: 46210 | O4: BODEGA KIKES | P4: 112207 | Q4: KI | R4: 0 | T4: LANZA | U4: PLANTA CLASIFICACION | V4: XL | W4: EMPACADOS | X4: - | Y4: SANTANDER | Z4: 0 | AA4: BODEGA | AB4: 0

Sheet RESUMEN
N7: EDADES CEDIS MAYOR A 5 DIAS | U7: EDADES PLANTAS MAYOR A 4 DÍAS
AE8: TIPO DE HUEVO 2 | AF8: VERDE
N9: Edad | O9: (Varios elementos) | U9: Edad | V9: (Varios elementos)
AC10: TIPO DE HUEVO 2 | AD10: VERDE | AE10: Prom Actual
B11: Etiquetas de fila | C11: CANTIDADES | E11: cantidad | F11: Etiquetas de columna | N11: Suma de CANTIDAD | O11: tipo | U11: Suma de CANTIDAD | V11: tipo | AE11: 760492.5
B12: VEHICULOS | C12: 2489681 | E12: Etiquetas de fila | F12: VERDE | G12: SEGUNDA | H12: HUEVO SIN CLASIFICAR | I12: GRIS SUELTO | J12: ETIQUETA | K12: EMPACADOS | L12: Total general | N12: DESTINO | O12: VERDE | P12: EMPACADOS | Q12: Total general | U12: DESTINO | V12: VERDE | W12: GRIS SUELTO | X12: SEGUNDA | Y12: Total general | AC12: Etiquetas de fila | AD12: CANTIDAD. | AE12: DIAS DE INVENTARIO | AJ12: INVENTARIO POR PLANTA
B13: BODEGA | C13: 8194931 | E13: BODEGA | F13: 3488265 | G13: 26180 | I13: 2549331 | J13: 5647 | K13: 2125508 | L13: 8194931 | N13: TAT BARRANQUILLA | O13: 206275 | P13: 9360 | Q13: 215635 | U13: ALKA1 | W13: 13370 | Y13: 13370 | AC13: VEHICULOS | AD13: 743277 | AE13: =AD13/$AE$11 -> 0.9773627 | AJ13: TIPO | AK13: LANZA | AL13: BELLAVISTA | AM13: ALKA 1 | AN13: ALKA 2 | AO13: PALMAS | AP13: BQ | AQ13: MONTERIA | AR13: CALI | AS13: BODEGA KIGT | AT13: TOTAL
B14: TRANSITO | C14: 4854662 | E14: HUEVO SIN CLASIFICAR | H14: 2746557 | L14: 2746557 | N14: TAT BOGOTA MONTEVIDEO | O14: 117120 | P14: 51955 | Q14: 169075 | U14: ALKA2 | V14: 48669 | Y14: 48669 | AC14: BODEGA | AD14: 1371925 | AE14: =AD14/$AE$11 -> 1.8039954 | AJ14: AAA | AK14: 4530 | AL14: 0 | AM14: 10275 | AN14: 0 | AO14: 45069 | AP14: 0 | AQ14: 0 | AR14: 0 | AS14: 0 | AT14: 59874
B15: PLANTA CLASIFICACION | C15: 4431580 | E15: PLANTA CLASIFICACION | F15: 1398924 | G15: 593943 | I15: 2012773 | K15: 425940 | L15: 4431580 | N15: TAT BOGOTA SIBERIA | O15: 54720 | P15: 1560 | Q15: 56280 | U15: BELLAVISTA | W15: 18532 | X15: 1846 | Y15: 20378 | AC15: TRANSITO | AD15: 792024 | AE15: =AD15/$AE$11 -> 1.0414619 | AJ15: AA | AK15: 30030 | AL15: 0 | AM15: 15450 | AN15: 0 | AO15: 35109 | AP15: 0 | AQ15: 0 | AR15: 0 | AS15: 0 | AT15: 80589
B16: HUEVO SIN CLASIFICAR | C16: 2746557 | E16: TRANSITO | F16: 1895244 | I16: 2460260 | J16: 12000 | K16: 487158 | L16: 4854662 | N16: TAT CALI | O16: 67556 | P16: 2595 | Q16: 70151 | U16: PALMAS | W16: 12788 | Y16: 12788 | AC16: PLANTA CLASIFICACION | AD16: 463103 | AE16: =AD16/$AE$11 -> 0.60895144 | AJ16: A | AK16: 16080 | AL16: 0 | AM16: 9723 | AN16: 0 | AO16: 18346 | AP16: 0 | AQ16: 0 | AR16: 0 | AS16: 0 | AT16: 44149
B17: Total general | C17: 22717411 | E17: VEHICULOS | F17: 2230735 | J17: 21425 | K17: 237521 | L17: 2489681 | N17: TAT CARTAGENA | P17: 34488 | Q17: 34488 | U17: Total general | V17: 48669 | W17: 44690 | X17: 1846 | Y17: 95205 | AC17: Total general | AD17: 3370329 | AE17: =SUM(AE13:AE16) -> 4.4317715 | AJ17: B | AK17: 2580 | AL17: 0 | AM17: 492 | AN17: 0 | AO17: 6548 | AP17: 0 | AQ17: 0 | AR17: 0 | AS17: 0 | AT17: 9620
E18: Total general | F18: 9013168 | G18: 620123 | H18: 2746557 | I18: 7022364 | J18: 39072 | K18: 3276127 | L18: 22717411 | N18: TAT MEDELLIN | O18: 215580 | P18: 5940 | Q18: 221520 | AJ18: C | AK18: 25680 | AL18: 99398 | AM18: 9212 | AN18: 9810 | AO18: 29832 | AP18: 0 | AQ18: 0 | AR18: 0 | AS18: 0 | AT18: 173932
N19: TAT PASTO | O19: 19623 | P19: 10590 | Q19: 30213 | AJ19: SEGUNDA | AK19: 8100 | AL19: 23895 | AM19: 0 | AN19: 0 | AO19: 0 | AP19: 0 | AQ19: 0 | AR19: 0 | AS19: 0 | AT19: 31995
N20: TAT VALLEDUPAR | O20: 70726 | Q20: 70726 | AJ20: TOTAL | AK20: 87000 | AL20: 123293 | AM20: 45152 | AN20: 9810 | AO20: 134904 | AP20: 0 | AQ20: 0 | AR20: 0 | AS20: 0 | AT20: 400159
N21: TAT VILLAVICENCIO | O21: 13754 | Q21: 13754 | U21: PLANTAS | V21: CAP TOTAL | W21: CAP CON EQUIPO | X21: TOTAL PLANTA | Y21: % | AC21: CEDIS | AD21: CAP MAXIMA | AE21: TOTAL CEDI | AF21: %
N22: TAT BUCARAMANGA | P22: 14004 | Q22: 14004 | U22: ALKA1 | V22: 4134960 | W22: 3199960 | X22: =SUMIF(inv!T$1:T$1164,RESUMEN!U22,inv!D$1:D$1164) -> 852724 | Y22: =X22/W22 -> 0.26647958 | AC22: TAT PEREIRA | AD22: 226000 | AE22: =SUMIFS(inv!D$1:D$1164,inv!T$1:T$1164,RESUMEN!AC22,inv!U$1:U$1164,"<>VEHICULOS") -> 30427 | AF22: =AE22/AD22 -> 0.13463274
N23: TAT CUCUTA | O23: 57350 | P23: 1920 | Q23: 59270 | U23: ALKA2 | V23: 1247760 | W23: 907760 | X23: =SUMIF(inv!T$1:T$1164,RESUMEN!U23,inv!D$1:D$1164) -> 749062 | Y23: =X23/W23 -> 0.82517626 | AC23: TAT VALLEDUPAR | AD23: 450000 | AE23: =SUMIFS(inv!D$1:D$1164,inv!T$1:T$1164,RESUMEN!AC23,inv!U$1:U$1164,"<>VEHICULOS") -> 175663 | AF23: =AE23/AD23 -> 0.39036222
N24: TAT MONTERIA | O24: 124807 | P24: 1710 | Q24: 126517 | U24: PALMAS | V24: 2085120 | W24: 1575120 | X24: =SUMIF(inv!T$1:T$1164,RESUMEN!U24,inv!D$1:D$1164) -> 1062135 | Y24: =X24/W24 -> 0.67432005 | AC24: TAT BUCARAMANGA | AD24: 200000 | AE24: =SUMIFS(inv!D$1:D$1164,inv!T$1:T$1164,RESUMEN!AC24,inv!U$1:U$1164,"<>VEHICULOS") -> 224814 | AF24: =AE24/AD24 -> 1.12407
N25: TAT SANTA MARTA | P25: 2457 | Q25: 2457 | U25: BELLAVISTA | V25: 3200000 | W25: 2100000 | X25: =SUMIF(inv!T$1:T$1164,RESUMEN!U25,inv!D$1:D$1164) -> 430976 | Y25: =X25/W25 -> 0.20522667 | AC25: TAT BOGOTA MONTEVIDEO | AD25: 1486000 | AE25: =SUMIFS(inv!D$1:D$1164,inv!T$1:T$1164,RESUMEN!AC25,inv!U$1:U$1164,"<>VEHICULOS") -> 910912 | AF25: =AE25/AD25 -> 0.61299596
N26: Total general | O26: 947511 | P26: 136579 | Q26: 1084090 | U26: LANZA | V26: 2500000 | W26: 2500000 | X26: =SUMIF(inv!T$1:T$1164,RESUMEN!U26,inv!D$1:D$1164) -> 1976014 | Y26: =X26/W26 -> 0.7904056 | AC26: TAT BOGOTA SIBERIA | AD26: 835800 | AE26: =SUMIFS(inv!D$1:D$1164,inv!T$1:T$1164,RESUMEN!AC26,inv!U$1:U$1164,"<>VEHICULOS") -> 132806 | AF26: =AE26/AD26 -> 0.15889687
AC27: TAT CE BOGOTA | AD27: 713000 | AE27: =SUMIFS(inv!D$1:D$1164,inv!T$1:T$1164,RESUMEN!AC27,inv!U$1:U$1164,"<>VEHICULOS") -> 1474546 | AF27: =AE27/AD27 -> 2.068087
AC28: TAT MONTERIA | AD28: 359040 | AE28: =SUMIFS(inv!D$1:D$1164,inv!T$1:T$1164,RESUMEN!AC28,inv!U$1:U$1164,"<>VEHICULOS") -> 286186 | AF28: =AE28/AD28 -> 0.79708668
AC29: TAT CARTAGENA | AD29: 864000 | AE29: =SUMIFS(inv!D$1:D$1164,inv!T$1:T$1164,RESUMEN!AC29,inv!U$1:U$1164,"<>VEHICULOS") -> 1236253 | AF29: =AE29/AD29 -> 1.4308484
AC30: TAT CALI | AD30: 910440 | AE30: =SUMIFS(inv!D$1:D$1164,inv!T$1:T$1164,RESUMEN!AC30,inv!U$1:U$1164,"<>VEHICULOS") -> 566851 | AF30: =AE30/AD30 -> 0.62261214
AC31: TAT MEDELLIN | AD31: 950400 | AE31: =SUMIFS(inv!D$1:D$1164,inv!T$1:T$1164,RESUMEN!AC31,inv!U$1:U$1164,"<>VEHICULOS") -> 887995 | AF31: =AE31/AD31 -> 0.93433817
AC32: TAT PASTO | AD32: 900000 | AE32: =SUMIFS(inv!D$1:D$1164,inv!T$1:T$1164,RESUMEN!AC32,inv!U$1:U$1164,"<>VEHICULOS") -> 536155 | AF32: =AE32/AD32 -> 0.59572778
B33: Etiquetas de fila | C33: Inventario | D33: Venta Mes | E33: Días de Venta | F33: Venta/Día | G33: Días de Inv | H33: Ventas Prom | I33: Días de Inv | J33: Días Ideales | K33: Inv Ideal | L33: Inv-ideal | AC33: TAT SANTA MARTA | AD33: 450000 | AE33: =SUMIFS(inv!D$1:D$1164,inv!T$1:T$1164,RESUMEN!AC33,inv!U$1:U$1164,"<>VEHICULOS") -> 237649 | AF33: =AE33/AD33 -> 0.52810889
B34: TAT | C34: 9896112 | D34: 58260250 | E34: 25 | F34: =D34/E34 -> 2330410 | G34: =C34/F34 -> 4.2465111 | H34: =SUMIFS('VENTAS CANAL'!$O:$O,'VENTAS CANAL'!$N:$N,RESUMEN!B34) -> 1622445.7 | I34: =IFERROR((C34/H34),0) -> 6.0995029 | J34: 5 | K34: =H34*J34 -> 8112228.3 | L34: =+GETPIVOTDATA("cantidad",$B$33,"CANAL","TAT")-K34 -> 1783883.7 | AC34: TAT POPAYAN | AD34: 460000 | AE34: =SUMIFS(inv!D$1:D$1164,inv!T$1:T$1164,RESUMEN!AC34,inv!U$1:U$1164,"<>VEHICULOS") -> 463597 | AF34: =AE34/AD34 -> 1.0078196
B35: HD | C35: 8074772 | D35: 62000000 | E35: 28 | F35: =D35/E35 -> 2214285.7 | G35: =C35/F35 -> 3.6466712 | H35: =SUMIFS('VENTAS CANAL'!$O:$O,'VENTAS CANAL'!$N:$N,RESUMEN!B35) -> 2359374 | I35: =IFERROR((C35/H35),0) -> 3.4224214 | J35: 3.5 | K35: =H35*J35 -> 8257809 | L35: =+GETPIVOTDATA("cantidad",$B$33,"CANAL","HD")-K35 -> -183037 | AC35: TAT CUCUTA | AD35: 600000 | AE35: =SUMIFS(inv!D$1:D$1164,inv!T$1:T$1164,RESUMEN!AC35,inv!U$1:U$1164,"<>VEHICULOS") -> 254772 | AF35: =AE35/AD35 -> 0.42462
B36: AU/FS/GS | C36: 896242 | D36: 20650000 | E36: 25 | F36: =D36/E36 -> 826000 | G36: =C36/F36 -> 1.0850387 | H36: =SUMIFS('VENTAS CANAL'!$O:$O,'VENTAS CANAL'!$N:$N,RESUMEN!B36) -> 499374.67 | I36: =IFERROR((C36/H36),0) -> 1.7947286 | J36: 3 | K36: =H36*J36 -> 1498124 | L36: =+GETPIVOTDATA("cantidad",$B$33,"CANAL","AU/FS/GS")-K36 -> -601882 | AC36: TAT CE BARRANQUILLA | AD36: 2534400 | AE36: =SUMIFS(inv!D$1:D$1164,inv!T$1:T$1164,RESUMEN!AC36,inv!U$1:U$1164,"<>VEHICULOS") -> 2514933 | AF36: =AE36/AD36 -> 0.99231889
B37: MAY | C37: 483605 | D37: 7436798.7 | E37: 25 | F37: =D37/E37 -> 297471.95 | G37: =C37/F37 -> 1.6257163 | H37: =SUMIFS('VENTAS CANAL'!$O:$O,'VENTAS CANAL'!$N:$N,RESUMEN!B37) -> 63258 | I37: =IFERROR((C37/H37),0) -> 7.6449619 | J37: 3 | K37: =H37*J37 -> 189774 | L37: =+GETPIVOTDATA("cantidad",$B$33,"CANAL","MAY")-K37 -> 293831 | AC37: TAT CE MONTERIA | AD37: 673200 | AE37: =SUMIFS(inv!D$1:D$1164,inv!T$1:T$1164,RESUMEN!AC37,inv!U$1:U$1164,"<>VEHICULOS") -> 868584 | AF37: =AE37/AD37 -> 1.2902317
B38: SEGUNDA | C38: 620123 | D38: 6342000 | E38: 25 | F38: =D38/E38 -> 253680 | G38: =C38/F38 -> 2.4445088 | H38: =SUMIFS('VENTAS CANAL'!$O:$O,'VENTAS CANAL'!$N:$N,RESUMEN!B38) -> 252615 | I38: =IFERROR((C38/H38),0) -> 2.4548146 | J38: 3 | K38: =H38*J38 -> 757845 | L38: =+GETPIVOTDATA("cantidad",$B$33,"CANAL","SEGUNDA")-K38 -> -137722 | AC38: TAT BARRANQUILLA | AD38: 950400 | AE38: =SUMIFS(inv!D$1:D$1164,inv!T$1:T$1164,RESUMEN!AC38,inv!U$1:U$1164,"<>VEHICULOS") -> 792770 | AF38: =AE38/AD38 -> 0.83414352
B39: SIN CL | C39: 2746557 | D39: 45589609 | E39: 30 | F39: =D39/E39 -> 1519653.6 | G39: =C39/F39 -> 1.8073573 | H39: =F39 -> 1519653.6 | I39: =IFERROR((C39/H39),0) -> 1.8073573 | J39: 1.5 | K39: =H39*J39 -> 2279480.4 | L39: =+GETPIVOTDATA("cantidad",$B$33,"CANAL","SIN CL")-K39 -> 467076.56 | AC39: TAT SINCELEJO | AD39: 400000 | AE39: =SUMIFS(inv!D$1:D$1164,inv!T$1:T$1164,RESUMEN!AC39,inv!U$1:U$1164,"<>VEHICULOS") -> 37518 | AF39: =AE39/AD39 -> 0.093795
B40: Total general | C40: 22717411 | F40: =+SUM(F34:F38) -> 5921847.7 | G40: =C40/F40 -> 3.8362032 | H40: =+SUM(H34:H38) -> 4797067.3 | K40: =SUM(K34:K39) -> 21095261 | L40: =+SUM(L34:L39) -> 1622150.2 | AC40: TAT VILLAVICENCIO | AD40: 110000 | AE40: =SUMIFS(inv!D$1:D$1164,inv!T$1:T$1164,RESUMEN!AC40,inv!U$1:U$1164,"<>VEHICULOS") -> 82874 | AF40: =AE40/AD40 -> 0.7534

Sheet EDADES
A1: VOLVER
D6: DESTINO | E6: Edad | F6: Item | G6: Referencia | H6: Suma de CANTIDAD2
D7: ALKA1 | E7: 8 | F7: 75201 | G7: HUEVO AAA X 30 CARTON GRIS LZ | H7: 4224
D8: ALKA1 | E8: 7 | F8: 75201 | G8: HUEVO AAA X 30 CARTON GRIS LZ | H8: 3206
D9: ALKA1 | E9: 6 | F9: 75201 | G9: HUEVO AAA X 30 CARTON GRIS LZ | H9: 5940
D10: ALKA1 | E10: 4 | F10: 75201 | G10: HUEVO AAA X 30 CARTON GRIS LZ | H10: 8038
D11: ALKA1 | E11: 4 | F11: 75301 | G11: HUEVO AA X 30 CARTON GRIS LZ | H11: 90
D12: ALKA1 | E12: 4 | F12: 75401 | G12: HUEVO A X 30 CARTON GRIS LZ | H12: 76
D13: ALKA1 | E13: 4 | F13: 75501 | G13: HUEVO B X 30 CARTON GRIS LZ | H13: 172
D14: ALKA1 | E14: 4 | F14: 79110 | G14: HUEVO ROTO - ZF | H14: 3300
D15: ALKA1 | E15: 4 | F15: 2110402 | G15: HUEVO M X 30 CARTON VERDE CANASTA | H15: 120
D16: ALKA1 | E16: 4 | F16: 2110202 | G16: HUEVO XL X 30 CARTON VERDE CANASTA | H16: 31317
D17: ALKA1 | E17: 3 | F17: 10601 | G17: HUEVO CX30 CARTON GRIS | H17: 98
D18: ALKA1 | E18: 3 | F18: 73001 | G18: HUEVO PICADO ROJO | H18: 18109
... D46: ALKA1 | E46: 1 | F46: 2410401 | G46: HUEVO CE X 30 CARTON GRIS CANASTA | H46: 302316
D47: Total ALKA1 | H47: 852724
D48: ALKA2 | E48: 6 | F48: 2110202 | G48: HUEVO XL X 30 CARTON VERDE CANASTA | H48: 25200
D49: ALKA2 | E49: 5 | F49: 2110202 | G49: HUEVO XL X 30 CARTON VERDE CANASTA | H49: 22509
D50: ALKA2 | E50: 5 | F50: 2010102 | G50: HUEVO YUMBO X20 CARTON VERDE CANASTA | H50: 960
D51: ALKA2 | E51: 4 | F51: 2110202 | G51: HUEVO XL X 30 CARTON VERDE CANASTA | H51: 44455
D52: ALKA2 | E52: 4 | F52: 2010102 | G52: HUEVO YUMBO X20 CARTON VERDE CANASTA | H52: 1352
D53: ALKA2 | E53: 3 | F53: 10601 | G53: HUEVO CX30 CARTON GRIS | H53: 1747
D54: ALKA2 | E54: 3 | F54: 73001 | G54: HUEVO PICADO ROJO | H54: 10577
D55: ALKA2 | E55: 3 | F55: 2110402 | G55: HUEVO M X 30 CARTON VERDE CANASTA | H55: 3257
D56: ALKA2 | E56: 3 | F56: 2110202 | G56: HUEVO XL X 30 CARTON VERDE CANASTA | H56: 29929
D57: ALKA2 | E57: 3 | F57: 2010102 | G57: HUEVO YUMBO X20 CARTON VERDE CANASTA | H57: 1014
D58: ALKA2 | E58: 2 | F58: 10601 | G58: HUEVO CX30 CARTON GRIS | H58: 3684
D59: ALKA2 | E59: 2 | F59: 72003 | G59: HUEVO SUCIO ZF MARCADO | H59: 3240
... D73: ALKA2 | E73: 1 | F73: 2410401 | G73: HUEVO CE X 30 CARTON GRIS CANASTA | H73: 180747
D74: Total ALKA2 | H74: 748353
D75: BELLAVISTA | E75: 6 | F75: 79101 | G75: HUEVO ROTO | H75: 1046
D76: BELLAVISTA | E76: 5 | F76: 10601 | G76: HUEVO CX30 CARTON GRIS | H76: 18532
D77: BELLAVISTA | E77: 5 | F77: 79101 | G77: HUEVO ROTO | H77: 800
D78: BELLAVISTA | E78: 4 | F78: 10501 | G78: HUEVO B X30 CARTON GRIS | H78: 19844
D79: BELLAVISTA | E79: 4 | F79: 10601 | G79: HUEVO CX30 CARTON GRIS | H79: 27498
D80: BELLAVISTA | E80: 4 | F80: 79101 | G80: HUEVO ROTO | H80: 1253
D81: BELLAVISTA | E81: 4 | F81: 79111 | G81: HUEVO ROTO ZF- SANTANDER | H81: 5235
D82: BELLAVISTA | E82: 4 | F82: 2010501 | G82: HUEVO B X30 CARTON GRIS CANASTA | H82: 3918
D83: BELLAVISTA | E83: 3 | F83: 10501 | G83: HUEVO B X30 CARTON GRIS | H83: 18444
D84: BELLAVISTA | E84: 3 | F84: 10601 | G84: HUEVO CX30 CARTON GRIS | H84: 28691
...

Sheet GESTION EDADES
C3: GESTION DE DESECHO / ZF | L3: EDADES ALTAS EN PLANTAS Y CENTRO EMPAQUES | T3: EDADES ALTAS EN CEDIS
C4: CEDI | D4: (Varios elementos)
C5: Gestion desecho/zf | D5: Aplica | L5: Edad Alta | M5: No aplica | T5: Cedis | U5: No aplica
C7: DESTINO | D7: Edad | E7: Item | F7: Referencia | G7: CANTIDAD. | L7: DESTINO | M7: Edad | N7: Item | O7: Referencia | P7: Suma de CANTIDAD | T7: DESTINO | U7: Edad | V7: Item | W7: Referencia | X7: Suma de CANTIDAD
C8: ALKA1 | D8: 8 | E8: 75201 | F8: HUEVO AAA X 30 CARTON GRIS LZ | G8: 4224 | L8: ALKA1 | M8: 8 | N8: 75201 | O8: HUEVO AAA X 30 CARTON GRIS LZ | P8: 4224 | T8: ALKA1 | U8: 1 | V8: 10601 | W8: HUEVO CX30 CARTON GRIS | X8: 4344
C9: ALKA1 | D9: 7 | E9: 75201 | F9: HUEVO AAA X 30 CARTON GRIS LZ | G9: 3206 | L9: ALKA1 | M9: 7 | N9: 75201 | O9: HUEVO AAA X 30 CARTON GRIS LZ | P9: 3206 | T9: ALKA1 | U9: 1 | V9: 72002 | W9: HUEVO SUCIO ZF | X9: 3210
C10: ALKA1 | D10: 6 | E10: 75201 | F10: HUEVO AAA X 30 CARTON GRIS LZ | G10: 5940 | L10: ALKA1 | M10: 6 | N10: 75201 | O10: HUEVO AAA X 30 CARTON GRIS LZ | P10: 5940 | T10: ALKA1 | U10: 1 | V10: 73001 | W10: HUEVO PICADO ROJO | X10: 20910
C11: Total ALKA1 | G11: 13370 | L11: ALKA1 | M11: 4 | N11: 75201 | O11: HUEVO AAA X 30 CARTON GRIS LZ | P11: 8038 | T11: ALKA1 | U11: 1 | V11: 75201 | W11: HUEVO AAA X 30 CARTON GRIS LZ | X11: 570
C12: ALKA2 | D12: 2 | E12: 72003 | F12: HUEVO SUCIO ZF MARCADO | G12: 3240 | L12: ALKA1 | M12: 4 | N12: 75301 | O12: HUEVO AA X 30 CARTON GRIS LZ | P12: 90 | T12: ALKA1 | U12: 1 | V12: 75301 | W12: HUEVO AA X 30 CARTON GRIS LZ | X12: 4080
C13: Total ALKA2 | G13: 3240 | L13: ALKA1 | M13: 4 | N13: 75401 | O13: HUEVO A X 30 CARTON GRIS LZ | P13: 76 | T13: ALKA1 | U13: 1 | V13: 75401 | W13: HUEVO A X 30 CARTON GRIS LZ | X13: 3360
C14: BELLAVISTA | D14: 4 | E14: 79111 | F14: HUEVO ROTO ZF- SANTANDER | G14: 5235 | L14: ALKA1 | M14: 4 | N14: 75501 | O14: HUEVO B X 30 CARTON GRIS LZ | P14: 172 | T14: ALKA1 | U14: 1 | V14: 75501 | W14: HUEVO B X 30 CARTON GRIS LZ | X14: 260
C15: BELLAVISTA | D15: 3 | E15: 79111 | F15: HUEVO ROTO ZF- SANTANDER | G15: 6057 | L15: ALKA1 | M15: 4 | N15: 79110 | O15: HUEVO ROTO - ZF | P15: 3300 | T15: ALKA1 | U15: 1 | V15: 79110 | W15: HUEVO ROTO - ZF | X15: 7800
C16: BELLAVISTA | D16: 2 | E16: 79111 | F16: HUEVO ROTO ZF- SANTANDER | G16: 5403 | L16: ALKA1 | M16: 4 | N16: 2110202 | O16: HUEVO XL X 30 CARTON VERDE CANASTA | P16: 31317 | T16: ALKA1 | U16: 1 | V16: 112268 | W16: HUEVO XL X 15 PET CAJA X 300 | X16: 39000
C17: BELLAVISTA | D17: 2 | E17: 271901 | F17: HUEVO MAL MARCADO CANASTA | G17: 170 | L17: ALKA1 | M17: 4 | N17: 2110402 | O17: HUEVO M X 30 CARTON VERDE CANASTA | P17: 120 | T17: ALKA1 | U17: 1 | V17: 2010102 | W17: HUEVO YUMBO X20 CARTON VERDE CANASTA | X17: 2471
C18: BELLAVISTA | D18: 2 | E18: 273003 | F18: HUEVO PICADO ZF MARCADO X 30 BANDEJAS GRIS CANASTA | G18: 1615 | L18: ALKA1 | M18: 3 | N18: 10601 | O18: HUEVO CX30 CARTON GRIS | P18: 98 | T18: ALKA1 | U18: 1 | V18: 2010301 | W18: HUEVO AA X30 CARTON GRIS CANASTA | X18: 182400
C19: BELLAVISTA | D19: 1 | E19: 72003 | F19: HUEVO SUCIO ZF MARCADO | G19: 238 | L19: ALKA1 | M19: 3 | N19: 73001 | O19: HUEVO PICADO ROJO | P19: 18109 | T19: ALKA1 | U19: 1 | V19: 2010501 | W19: HUEVO B X30 CARTON GRIS CANASTA | X19: 1989
C20: BELLAVISTA | D20: 1 | E20: 79111 | F20: HUEVO ROTO ZF- SANTANDER | G20: 7200 | L20: ALKA1 | M20: 3 | N20: 79110 | O20: HUEVO ROTO - ZF | P20: 10500 | T20: ALKA1 | U20: 1 | V20: 2110202 | W20: HUEVO XL X 30 CARTON VERDE CANASTA | X20: 25740
C21: BELLAVISTA | D21: 1 | E21: 271901 | F21: HUEVO MAL MARCADO CANASTA | G21: 175 | L21: ALKA1 | M21: 3 | N21: 2010102 | O21: HUEVO YUMBO X20 CARTON VERDE CANASTA | P21: 40 | T21: ALKA1 | U21: 1 | V21: 2110302 | W21: HUEVO L X 30 CARTON VERDE CANASTA | X21: 23256
C22: BELLAVISTA | D22: 1 | E22: 273003 | F22: HUEVO PICADO ZF MARCADO X 30 BANDEJAS GRIS CANASTA | G22: 685 | L22: ALKA1 | M22: 3 | N22: 2110202 | O22: HUEVO XL X 30 CARTON VERDE CANASTA | P22: 17160 | T22: ALKA1 | U22: 1 | V22: 2410401 | W22: HUEVO CE X 30 CARTON GRIS CANASTA | X22: 302316
C23: Total BELLAVISTA | G23: 26778 | L23: ALKA1 | M23: 2 | N23: 10601 | O23: HUEVO CX30 CARTON GRIS | P23: 4770 | T23: ALKA1 | U23: 2 | V23: 10601 | W23: HUEVO CX30 CARTON GRIS | X23: 4770
C24: LANZA | D24: 4 | E24: 79111 | F24: HUEVO ROTO ZF- SANTANDER | G24: 2400 | L24: ALKA1 | M24: 2 | N24: 73001 | O24: HUEVO PICADO ROJO | P24: 23404 | T24: ALKA1 | U24: 2 | V24: 73001 | W24: HUEVO PICADO ROJO | X24: 23404
C25: LANZA | D25: 3 | E25: 79111 | F25: HUEVO ROTO ZF- SANTANDER | G25: 3300 | L25: ALKA1 | M25: 2 | N25: 75201 | O25: HUEVO AAA X 30 CARTON GRIS LZ | P25: 1667 | T25: ALKA1 | U25: 2 | V25: 75201 | W25: HUEVO AAA X 30 CARTON GRIS LZ | X25: 1667
C26: LANZA | D26: 2 | E26: 79111 | F26: HUEVO ROTO ZF- SANTANDER | G26: 2400 | L26: ALKA1 | M26: 2 | N26: 75301 | O26: HUEVO AA X 30 CARTON GRIS LZ | P26: 11280 | T26: ALKA1 | U26: 2 | V26: 75301 | W26: HUEVO AA X 30 CARTON GRIS LZ | X26: 11280
C27: LANZA | D27: 2 | E27: 272003 | F27: HUEVO SUCIO ZF MARCADO X 30 BANDEJA GRIS CANASTA | G27: 6690 | L27: ALKA1 | M27: 2 | N27: 75401 | O27: HUEVO A X 30 CARTON GRIS LZ | P27: 6287 | T27: ALKA1 | U27: 2 | V27: 75401 | W27: HUEVO A X 30 CARTON GRIS LZ | X27: 6287
C28: LANZA | D28: 2 | E28: 273003 | F28: HUEVO PICADO ZF MARCADO X 30 BANDEJAS GRIS CANASTA | G28: 3630 | L28: ALKA1 | M28: 2 | N28: 75501 | O28: HUEVO B X 30 CARTON GRIS LZ | P28: 60 | T28: ALKA1 | U28: 2 | V28: 75501 | W28: HUEVO B X 30 CARTON GRIS LZ | X28: 60
C29: Total LANZA | G29: 18420 | L29: ALKA1 | M29: 2 | N29: 79110 | O29: HUEVO ROTO - ZF | P29: 10200 | T29: ALKA1 | U29: 2 | V29: 79110 | W29: HUEVO ROTO - ZF | X29: 10200
C30: PALMAS | D30: 3 | E30: 72003 | F30: HUEVO SUCIO ZF MARCADO | G30: 24211 | L30: ALKA1 | M30: 2 | N30: 2010102 | O30: HUEVO YUMBO X20 CARTON VERDE CANASTA | P30: 2748 | T30: ALKA1 | U30: 2 | V30: 2010102 | W30: HUEVO YUMBO X20 CARTON VERDE CANASTA | X30: 2748
C31: PALMAS | D31: 2 | E31: 72003 | F31: HUEVO SUCIO ZF MARCADO | G31: 16570 | L31: ALKA1 | M31: 2 | N31: 2010301 | O31: HUEVO AA X30 CARTON GRIS CANASTA | P31: 42393 | T31: ALKA1 | U31: 2 | V31: 2010301 | W31: HUEVO AA X30 CARTON GRIS CANASTA | X31: 42393
C32: PALMAS | D32: 1 | E32: 72003 | F32: HUEVO SUCIO ZF MARCADO | G32: 15126 | L32: ALKA1 | M32: 2 | N32: 2110202 | O32: HUEVO XL X 30 CARTON VERDE CANASTA | P32: 25819 | T32: ALKA1 | U32: 2 | V32: 2110202 | W32: HUEVO XL X 30 CARTON VERDE CANASTA | X32: 25819
C33: Total PALMAS | G33: 55907 | L33: ALKA1 | M33: 1 | N33: 10601 | O33: HUEVO CX30 CARTON GRIS | P33: 4344 | T33: ALKA1 | U33: 3 | V33: 10601 | W33: HUEVO CX30 CARTON GRIS | X33: 98
C34: TAT CE BARRANQUILLA | D34: 7 | E34: 72001 | F34: HUEVO SUCIO DE JAULA | G34: 939 | L34: ALKA1 | M34: 1 | N34: 72002 | O34: HUEVO SUCIO ZF | P34: 3210 | T34: ALKA1 | U34: 3 | V34: 73001 | W34: HUEVO PICADO ROJO | X34: 18109
C35: Total TAT CE BARRANQUILLA | G35: 939 | L35: ALKA1 | M35: 1 | N35: 73001 | O35: HUEVO PICADO ROJO | P35: 20910 | T35: ALKA1 | U35: 3 | V35: 79110 | W35: HUEVO ROTO - ZF | X35: 10500
C36: Total general | G36: 118654 | L36: ALKA1 | M36: 1 | N36: 75201 | O36: HUEVO AAA X 30 CARTON GRIS LZ | P36: 570 | T36: ALKA1 | U36: 3 | V36: 2010102 | W36: HUEVO YUMBO X20 CARTON VERDE CANASTA | X36: 40
L37: ALKA1 | M37: 1 | N37: 75301 | O37: HUEVO AA X 30 CARTON GRIS LZ | P37: 4080 | T37: ALKA1 | U37: 3 | V37: 2110202 | W37: HUEVO XL X 30 CARTON VERDE CANASTA | X37: 17160
L38: ALKA1 | M38: 1 | N38: 75401 | O38: HUEVO A X 30 CARTON GRIS LZ | P38: 3360 | T38: ALKA1 | U38: 4 | V38: 75201 | W38: HUEVO AAA X 30 CARTON GRIS LZ | X38: 8038
L39: ALKA1 | M39: 1 | N39: 75501 | O39: HUEVO B X 30 CARTON GRIS LZ | P39: 260 | T39: ALKA1 | U39: 4 | V39: 75301 | W39: HUEVO AA X 30 CARTON GRIS LZ | X39: 90
L40: ALKA1 | M40: 1 | N40: 79110 | O40: HUEVO ROTO - ZF | P40: 7800 | T40: ALKA1 | U40: 4 | V40: 75401 | W40: HUEVO A X 30 CARTON GRIS LZ | X40: 76
L41: ALKA1 | M41: 1 | N41: 112268 | O41: HUEVO XL X 15 PET CAJA X 300 | P41: 39000 | T41: ALKA1 | U41: 4 | V41: 75501 | W41: HUEVO B X 30 CARTON GRIS LZ | X41: 172
L42: ALKA1 | M42: 1 | N42: 2010102 | O42: HUEVO YUMBO X20 CARTON VERDE CANASTA | P42: 2471 | T42: ALKA1 | U42: 4 | V42: 79110 | W42: HUEVO ROTO - ZF | X42: 3300
L43: ALKA1 | M43: 1 | N43: 2010301 | O43: HUEVO AA X30 CARTON GRIS CANASTA | P43: 182400 | T43: ALKA1 | U43: 4 | V43: 2110202 | W43: HUEVO XL X 30 CARTON VERDE CANASTA | X43: 31317
...

Sheet VENTA T
B2: 2010102
B3: YUMBO | G3: Días | H3: Días | I3: Días | J3: Días | K3: UND
B4: DESTINO | C4: VEHICULOS | D4: BODEGA | E4: TRANSITO | F4: PROM VENTA | G4: VEHICULOS | H4: BODEGA | I4: TRANSITO | J4: TOTAL | K4: CARGADAS
B5: TAT BOGOTA MONTEVIDEO | C5: =SUMIFS(inv!$D:$D,inv!$T:$T,'VENTA T'!$B5,inv!$U:$U,'VENTA T'!$C$4,inv!$A:$A,'VENTA T'!$B$2) -> 10590 | D5: =SUMIFS(inv!$D:$D,inv!$T:$T,'VENTA T'!$B5,inv!$U:$U,'VENTA T'!$D$4,inv!$A:$A,'VENTA T'!$B$2) -> 9676 | E5: =SUMIFS(inv!$D:$D,inv!$T:$T,'VENTA T'!$B5,inv!$U:$U,'VENTA T'!$E$4,inv!$A:$A,'VENTA T'!$B$2) -> 0 | F5: =SUMIFS(VENTAS!$H:$H,VENTAS!$G:$G,'VENTA T'!$B5,VENTAS!$B:$B,'VENTA T'!$B$2) -> 5122 | G5: =C5/$F5 -> 2.0675517 | H5: =D5/$F5 -> 1.8891058 | I5: =E5/$F5 -> 0 | J5: =H5+I5 -> 1.8891058 | K5: =IFERROR(C5-F5,0) -> 5468
B6: TAT BOGOTA SIBERIA | C6: =SUMIFS(inv!$D:$D,inv!$T:$T,'VENTA T'!$B6,inv!$U:$U,'VENTA T'!$C$4,inv!$A:$A,'VENTA T'!$B$2) -> 5544 | D6: =SUMIFS(inv!$D:$D,inv!$T:$T,'VENTA T'!$B6,inv!$U:$U,'VENTA T'!$D$4,inv!$A:$A,'VENTA T'!$B$2) -> 820 | E6: =SUMIFS(inv!$D:$D,inv!$T:$T,'VENTA T'!$B6,inv!$U:$U,'VENTA T'!$E$4,inv!$A:$A,'VENTA T'!$B$2) -> 0 | F6: =SUMIFS(VENTAS!$H:$H,VENTAS!$G:$G,'VENTA T'!$B6,VENTAS!$B:$B,'VENTA T'!$B$2) -> 2202 | G6: =C6/$F6 -> 2.5177112 | H6: =D6/$F6 -> 0.37238874 | I6: =E6/$F6 -> 0 | J6: =H6+I6 -> 0.37238874 | K6: =IFERROR(C6-F6,0) -> 3342
B7: TAT CALI | C7: =SUMIFS(inv!$D:$D,inv!$T:$T,'VENTA T'!$B7,inv!$U:$U,'VENTA T'!$C$4,inv!$A:$A,'VENTA T'!$B$2) -> 5508 | D7: =SUMIFS(inv!$D:$D,inv!$T:$T,'VENTA T'!$B7,inv!$U:$U,'VENTA T'!$D$4,inv!$A:$A,'VENTA T'!$B$2) -> 20148 | E7: =SUMIFS(inv!$D:$D,inv!$T:$T,'VENTA T'!$B7,inv!$U:$U,'VENTA T'!$E$4,inv!$A:$A,'VENTA T'!$B$2) -> 0 | F7: =SUMIFS(VENTAS!$H:$H,VENTAS!$G:$G,'VENTA T'!$B7,VENTAS!$B:$B,'VENTA T'!$B$2) -> 6428.5 | G7: =C7/$F7 -> 0.85680952 | H7: =D7/$F7 -> 3.1341682 | I7: =E7/$F7 -> 0 | J7: =H7+I7 -> 3.1341682 | K7: =IFERROR(C7-F7,0) -> -920.5
B8: TAT MEDELLIN | C8: =SUMIFS(inv!$D:$D,inv!$T:$T,'VENTA T'!$B8,inv!$U:$U,'VENTA T'!$C$4,inv!$A:$A,'VENTA T'!$B$2) -> 1461 | D8: =SUMIFS(inv!$D:$D,inv!$T:$T,'VENTA T'!$B8,inv!$U:$U,'VENTA T'!$D$4,inv!$A:$A,'VENTA T'!$B$2) -> 1005 | E8: =SUMIFS(inv!$D:$D,inv!$T:$T,'VENTA T'!$B8,inv!$U:$U,'VENTA T'!$E$4,inv!$A:$A,'VENTA T'!$B$2) -> 9600 | F8: =SUMIFS(VENTAS!$H:$H,VENTAS!$G:$G,'VENTA T'!$B8,VENTAS!$B:$B,'VENTA T'!$B$2) -> 2757 | G8: =C8/$F8 -> 0.52992383 | H8: =D8/$F8 -> 0.36452666 | I8: =E8/$F8 -> 3.4820457 | J8: =H8+I8 -> 3.8465724 | K8: =IFERROR(C8-F8,0) -> -1296
B9: TAT PASTO | C9: =SUMIFS(inv!$D:$D,inv!$T:$T,'VENTA T'!$B9,inv!$U:$U,'VENTA T'!$C$4,inv!$A:$A,'VENTA T'!$B$2) -> 1172 | D9: =SUMIFS(inv!$D:$D,inv!$T:$T,'VENTA T'!$B9,inv!$U:$U,'VENTA T'!$D$4,inv!$A:$A,'VENTA T'!$B$2) -> 2483 | E9: =SUMIFS(inv!$D:$D,inv!$T:$T,'VENTA T'!$B9,inv!$U:$U,'VENTA T'!$E$4,inv!$A:$A,'VENTA T'!$B$2) -> 0 | F9: =SUMIFS(VENTAS!$H:$H,VENTAS!$G:$G,'VENTA T'!$B9,VENTAS!$B:$B,'VENTA T'!$B$2) -> 830 | G9: =C9/$F9 -> 1.4120482 | H9: =D9/$F9 -> 2.9915663 | I9: =E9/$F9 -> 0 | J9: =H9+I9 -> 2.9915663 | K9: =IFERROR(C9-F9,0) -> 342
B10: TAT POPAYAN | C10: =SUMIFS(inv!$D:$D,inv!$T:$T,'VENTA T'!$B10,inv!$U:$U,'VENTA T'!$C$4,inv!$A:$A,'VENTA T'!$B$2) -> 2372 | D10: =SUMIFS(inv!$D:$D,inv!$T:$T,'VENTA T'!$B10,inv!$U:$U,'VENTA T'!$D$4,inv!$A:$A,'VENTA T'!$B$2) -> 3383 | E10: =SUMIFS(inv!$D:$D,inv!$T:$T,'VENTA T'!$B10,inv!$U:$U,'VENTA T'!$E$4,inv!$A:$A,'VENTA T'!$B$2) -> 0 | F10: =SUMIFS(VENTAS!$H:$H,VENTAS!$G:$G,'VENTA T'!$B10,VENTAS!$B:$B,'VENTA T'!$B$2) -> 690 | G10: =C10/$F10 -> 3.4376812 | H10: =D10/$F10 -> 4.9028986 | I10: =E10/$F10 -> 0 | J10: =H10+I10 -> 4.9028986
C11: =SUM(C5:C10) -> 26647 | D11: =SUM(D5:D10) -> 37515 | E11: =SUM(E5:E10) -> 9600 | F11: =SUM(F5:F10) -> 18029.5
B13: 2110202 | F13: 110202
B14: XL | G14: Días | H14: Días | I14: Días | J14: Días | K14: UND
B15: DESTINO | C15: VEHICULOS | D15: BODEGA | E15: TRANSITO | F15: PROM VENTA | G15: VEHICULOS | H15: BODEGA | I15: TRANSITO | J15: TOTAL | K15: CARGADAS
B16: TAT BOGOTA MONTEVIDEO | C16: =SUMIFS(inv!$D:$D,inv!$T:$T,'VENTA T'!$B16,inv!$U:$U,'VENTA T'!$C$15,inv!$A:$A,'VENTA T'!$B$13) -> 175385 | D16: =SUMIFS(inv!$D:$D,inv!$T:$T,'VENTA T'!$B16,inv!$U:$U,'VENTA T'!$D$15,inv!$A:$A,'VENTA T'!$B$13) -> 196896 | E16: =SUMIFS(inv!$D:$D,inv!$T:$T,'VENTA T'!$B16,inv!$U:$U,'VENTA T'!$E$15,inv!$A:$A,'VENTA T'!$B$13) -> 126720 | F16: =SUMIFS(VENTAS!$H:$H,VENTAS!$G:$G,'VENTA T'!$B16,VENTAS!$B:$B,'VENTA T'!$B$13) -> 85424 | G16: =C16/$F16 -> 2.0531115 | H16: =D16/$F16 -> 2.304926 | I16: =E16/$F16 -> 1.4834239 | J16: =H16+I16 -> 3.7883499 | K16: =IFERROR(C16-F16,0) -> 89961
B17: TAT MEDELLIN | C17: =SUMIFS(inv!$D:$D,inv!$T:$T,'VENTA T'!$B17,inv!$U:$U,'VENTA T'!$C$15,inv!$A:$A,'VENTA T'!$B$13) -> 176469 | D17: =SUMIFS(inv!$D:$D,inv!$T:$T,'VENTA T'!$B17,inv!$U:$U,'VENTA T'!$D$15,inv!$A:$A,'VENTA T'!$B$13) -> 283896 | E17: =SUMIFS(inv!$D:$D,inv!$T:$T,'VENTA T'!$B17,inv!$U:$U,'VENTA T'!$E$15,inv!$A:$A,'VENTA T'!$B$13) -> 160560 | F17: =SUMIFS(VENTAS!$H:$H,VENTAS!$G:$G,'VENTA T'!$B17,VENTAS!$B:$B,'VENTA T'!$B$13) -> 139221 | G17: =C17/$F17 -> 1.2675458 | H17: =D17/$F17 -> 2.0391751 | I17: =E17/$F17 -> 1.1532743 | J17: =H17+I17 -> 3.1924494 | K17: =IFERROR(C17-F17,0) -> 37248
B18: TAT CALI | C18: =SUMIFS(inv!$D:$D,inv!$T:$T,'VENTA T'!$B18,inv!$U:$U,'VENTA T'!$C$15,inv!$A:$A,'VENTA T'!$B$13) -> 92535 | D18: =SUMIFS(inv!$D:$D,inv!$T:$T,'VENTA T'!$B18,inv!$U:$U,'VENTA T'!$D$15,inv!$A:$A,'VENTA T'!$B$13) -> 167060 | E18: =SUMIFS(inv!$D:$D,inv!$T:$T,'VENTA T'!$B18,inv!$U:$U,'VENTA T'!$E$15,inv!$A:$A,'VENTA T'!$B$13) -> 0 | F18: =SUMIFS(VENTAS!$H:$H,VENTAS!$G:$G,'VENTA T'!$B18,VENTAS!$B:$B,'VENTA T'!$F$13)+SUMIFS(VENTAS!$H:$H,VENTAS!$G:$G,'VENTA T'!$B18,VENTAS!$B:$B,'VENTA T'!$B$13) -> 78612.5 | G18: =C18/$F18 -> 1.1771029 | H18: =D18/$F18 -> 2.1251073 | I18: =E18/$F18 -> 0 | J18: =H18+I18 -> 2.1251073 | K18: =IFERROR(C18-F18,0) -> 13922.5
B19: TAT PASTO | C19: =SUMIFS(inv!$D:$D,inv!$T:$T,'VENTA T'!$B19,inv!$U:$U,'VENTA T'!$C$15,inv!$A:$A,'VENTA T'!$B$13) -> 26921 | D19: =SUMIFS(inv!$D:$D,inv!$T:$T,'VENTA T'!$B19,inv!$U:$U,'VENTA T'!$D$15,inv!$A:$A,'VENTA T'!$B$13) -> 90612 | E19: =SUMIFS(inv!$D:$D,inv!$T:$T,'VENTA T'!$B19,inv!$U:$U,'VENTA T'!$E$15,inv!$A:$A,'VENTA T'!$B$13) -> 0 | F19: =SUMIFS(VENTAS!$H:$H,VENTAS!$G:$G,'VENTA T'!$B19,VENTAS!$B:$B,'VENTA T'!$B$13) -> 31317.5 | G19: =C19/$F19 -> 0.85961523 | H19: =D19/$F19 -> 2.8933344 | I19: =E19/$F19 -> 0 | J19: =H19+I19 -> 2.8933344 | K19: =IFERROR(C19-F19,0) -> -4396.5
B20: TAT BOGOTA SIBERIA | C20: =SUMIFS(inv!$D:$D,inv!$T:$T,'VENTA T'!$B20,inv!$U:$U,'VENTA T'!$C$15,inv!$A:$A,'VENTA T'!$B$13) -> 57029 | D20: =SUMIFS(inv!$D:$D,inv!$T:$T,'VENTA T'!$B20,inv!$U:$U,'VENTA T'!$D$15,inv!$A:$A,'VENTA T'!$B$13) -> 54720 | E20: =SUMIFS(inv!$D:$D,inv!$T:$T,'VENTA T'!$B20,inv!$U:$U,'VENTA T'!$E$15,inv!$A:$A,'VENTA T'!$B$13) -> 0 | F20: =SUMIFS(VENTAS!$H:$H,VENTAS!$G:$G,'VENTA T'!$B20,VENTAS!$B:$B,'VENTA T'!$B$13) -> 22649 | G20: =C20/$F20 -> 2.5179478 | H20: =D20/$F20 -> 2.4160007 | I20: =E20/$F20 -> 0 | J20: =H20+I20 -> 2.4160007 | K20: =IFERROR(C20-F20,0) -> 34380
B21: TAT POPAYAN | C21: =SUMIFS(inv!$D:$D,inv!$T:$T,'VENTA T'!$B21,inv!$U:$U,'VENTA T'!$C$15,inv!$A:$A,'VENTA T'!$B$13) -> 9576 | D21: =SUMIFS(inv!$D:$D,inv!$T:$T,'VENTA T'!$B21,inv!$U:$U,'VENTA T'!$D$15,inv!$A:$A,'VENTA T'!$B$13) -> 27360 | E21: =SUMIFS(inv!$D:$D,inv!$T:$T,'VENTA T'!$B21,inv!$U:$U,'VENTA T'!$E$15,inv!$A:$A,'VENTA T'!$B$13) -> 0 | F21: =SUMIFS(VENTAS!$H:$H,VENTAS!$G:$G,'VENTA T'!$B21,VENTAS!$B:$B,'VENTA T'!$B$13) -> 4946.5 | G21: =C21/$F21 -> 1.9359143 | H21: =D21/$F21 -> 5.5311837 | I21: =E21/$F21 -> 0 | J21: =H21+I21 -> 5.5311837 | K21: =IFERROR(C21-F21,0) -> 4629.5
B22: TAT VILLAVICENCIO | C22: =SUMIFS(inv!$D:$D,inv!$T:$T,'VENTA T'!$B22,inv!$U:$U,'VENTA T'!$C$15,inv!$A:$A,'VENTA T'!$B$13) -> 0 | D22: =SUMIFS(inv!$D:$D,inv!$T:$T,'VENTA T'!$B22,inv!$U:$U,'VENTA T'!$D$15,inv!$A:$A,'VENTA T'!$B$13) -> 0 | E22: =SUMIFS(inv!$D:$D,inv!$T:$T,'VENTA T'!$B22,inv!$U:$U,'VENTA T'!$E$15,inv!$A:$A,'VENTA T'!$B$13) -> 0 | F22: =SUMIFS(VENTAS!$H:$H,VENTAS!$G:$G,'VENTA T'!$B22,VENTAS!$B:$B,'VENTA T'!$B$13) -> 0 | G22: =IFERROR((C22/$F22),0) -> 0 | H22: =IFERROR((D22/$F22),0) -> 0 | I22: =IFERROR((E22/$F22),0) -> 0 | J22: =H22+I22 -> 0 | K22: =IFERROR(C22-F22,0) -> 0
C23: =SUM(C16:C22) -> 537915 | D23: =SUM(D16:D22) -> 820544 | E23: =SUM(E16:E22) -> 287280 | F23: =SUM(F16:F21) -> 362170.5
B24: 2110327
B25: 2110302
B26: L | G26: Días | H26: Días | I26: Días | J26: Días | K26: UND
B27: DESTINO | C27: VEHICULOS | D27: BODEGA | E27: TRANSITO | F27: PROM VENTA | G27: VEHICULOS | H27: BODEGA | I27: TRANSITO | J27: TOTAL | K27: CARGADAS
B28: TAT PASTO | C28: =SUMIFS(inv!$D:$D,inv!$T:$T,'VENTA T'!$B28,inv!$U:$U,'VENTA T'!$C$27,inv!$A:$A,'VENTA T'!$B$25) -> 196026 | D28: =SUMIFS(inv!$D:$D,inv!$T:$T,'VENTA T'!$B28,inv!$U:$U,'VENTA T'!$D$27,inv!$A:$A,'VENTA T'!$B$25) -> 158495 | E28: =SUMIFS(inv!$D:$D,inv!$T:$T,'VENTA T'!$B28,inv!$U:$U,'VENTA T'!$E$27,inv!$A:$A,'VENTA T'!$B$25) -> 255360 | F28: =SUMIFS(VENTAS!$H:$H,VENTAS!$G:$G,'VENTA T'!$B28,VENTAS!$B:$B,'VENTA T'!$B$25) -> 151599.5 | G28: =C28/$F28 -> 1.2930518 | H28: =D28/$F28 -> 1.045485 | I28: =E28/$F28 -> 1.6844383 | J28: =H28+I28 -> 2.7299233 | K28: =IFERROR(C28-F28,0) -> 44426.5
B29: TAT POPAYAN | C29: =SUMIFS(inv!$D:$D,inv!$T:$T,'VENTA T'!$B29,inv!$U:$U,'VENTA T'!$C$27,inv!$A:$A,'VENTA T'!$B$25) -> 51315 | D29: =SUMIFS(inv!$D:$D,inv!$T:$T,'VENTA T'!$B29,inv!$U:$U,'VENTA T'!$D$27,inv!$A:$A,'VENTA T'!$B$25) -> 331200 | E29: =SUMIFS(inv!$D:$D,inv!$T:$T,'VENTA T'!$B29,inv!$U:$U,'VENTA T'!$E$27,inv!$A:$A,'VENTA T'!$B$25) -> 0 | F29: =SUMIFS(VENTAS!$H:$H,VENTAS!$G:$G,'VENTA T'!$B29,VENTAS!$B:$B,'VENTA T'!$B$25) -> 131012.5 | G29: =C29/$F29 -> 0.39168018 | H29: =D29/$F29 -> 2.5280031 | I29: =E29/$F29 -> 0 | J29: =H29+I29 -> 2.5280031 | K29: =IFERROR(C29-F29,0) -> -79697.5
B30: TAT BARRANQUILLA | C30: =SUMIFS(inv!$D:$D,inv!$T:$T,'VENTA T'!$B30,inv!$U:$U,'VENTA T'!$C$27,inv!$A:$A,'VENTA T'!$B$25) -> 132806 | D30: =SUMIFS(inv!$D:$D,inv!$T:$T,'VENTA T'!$B30,inv!$U:$U,'VENTA T'!$D$27,inv!$A:$A,'VENTA T'!$B$25) -> 407 | E30: =SUMIFS(inv!$D:$D,inv!$T:$T,'VENTA T'!$B30,inv!$U:$U,'VENTA T'!$E$27,inv!$A:$A,'VENTA T'!$B$25) -> 265920 | F30: =SUMIFS(VENTAS!$H:$H,VENTAS!$G:$G,'VENTA T'!$B30,VENTAS!$B:$B,'VENTA T'!$B$25) -> 94734 | G30: =C30/$F30 -> 1.4018832 | H30: =D30/$F30 -> 0.00429624 | I30: =E30/$F30 -> 2.8070175 | J30: =H30+I30 -> 2.8113138 | K30: =IFERROR(C30-F30,0) -> 38072
B31: TAT BOGOTA MONTEVIDEO | C31: =SUMIFS(inv!$D:$D,inv!$T:$T,'VENTA T'!$B31,inv!$U:$U,'VENTA T'!$C$27,inv!$A:$A,'VENTA T'!$B$25) -> 178163 | D31: =SUMIFS(inv!$D:$D,inv!$T:$T,'VENTA T'!$B31,inv!$U:$U,'VENTA T'!$D$27,inv!$A:$A,'VENTA T'!$B$25) -> 106235 | E31: =SUMIFS(inv!$D:$D,inv!$T:$T,'VENTA T'!$B31,inv!$U:$U,'VENTA T'!$E$27,inv!$A:$A,'VENTA T'!$B$25) -> 0 | F31: =SUMIFS(VENTAS!$H:$H,VENTAS!$G:$G,'VENTA T'!$B31,VENTAS!$B:$B,'VENTA T'!$B$25) -> 77841.333 | G31: =C31/$F31 -> 2.2887969 | H31: =D31/$F31 -> 1.3647634 | I31: =E31/$F31 -> 0 | J31: =H31+I31 -> 1.3647634 | K31: =IFERROR(C31-F31,0) -> 100321.67
B32: TAT CUCUTA | C32: =SUMIFS(inv!$D:$D,inv!$T:$T,'VENTA T'!$B32,inv!$U:$U,'VENTA T'!$C$27,inv!$A:$A,'VENTA T'!$B$25) -> 93424 | D32: =SUMIFS(inv!$D:$D,inv!$T:$T,'VENTA T'!$B32,inv!$U:$U,'VENTA T'!$D$27,inv!$A:$A,'VENTA T'!$B$25) -> 92500 | E32: =SUMIFS(inv!$D:$D,inv!$T:$T,'VENTA T'!$B32,inv!$U:$U,'VENTA T'!$E$27,inv!$A:$A,'VENTA T'!$B$25) -> 0 | F32: =SUMIFS(VENTAS!$H:$H,VENTAS!$G:$G,'VENTA T'!$B32,VENTAS!$B:$B,'VENTA T'!$B$25) -> 66412 | G32: =C32/$F32 -> 1.4067337 | H32: =D32/$F32 -> 1.3928206 | I32: =E32/$F32 -> 0 | J32: =H32+I32 -> 1.3928206 | K32: =IFERROR(C32-F32,0) -> 27012
B33: TAT BUCARAMANGA | C33: =SUMIFS(inv!$D:$D,inv!$T:$T,'VENTA T'!$B33,inv!$U:$U,'VENTA T'!$C$27,inv!$A:$A,'VENTA T'!$B$24) -> 14675 | D33: =SUMIFS(inv!$D:$D,inv!$T:$T,'VENTA T'!$B33,inv!$U:$U,'VENTA T'!$D$27,inv!$A:$A,'VENTA T'!$B$24) -> 67585 | E33: =SUMIFS(inv!$D:$D,inv!$T:$T,'VENTA T'!$B33,inv!$U:$U,'VENTA T'!$E$27,inv!$A:$A,'VENTA T'!$B$24) -> 46080 | F33: =SUMIFS(VENTAS!$H:$H,VENTAS!$G:$G,'VENTA T'!$B33,VENTAS!$B:$B,'VENTA T'!$B$24) -> 45663.5 | G33: =C33/$F33 -> 0.32137265 | H33: =D33/$F33 -> 1.4800661 | I33: =E33/$F33 -> 1.0091211 | J33: =H33+I33 -> 2.4891872 | K33: =IFERROR(C33-F33,0) -> -30988.5
B34: TAT CALI | C34: =SUMIFS(inv!$D:$D,inv!$T:$T,'VENTA T'!$B34,inv!$U:$U,'VENTA T'!$C$27,inv!$A:$A,'VENTA T'!$B$25) -> 75972 | D34: =SUMIFS(inv!$D:$D,inv!$T:$T,'VENTA T'!$B34,inv!$U:$U,'VENTA T'!$D$27,inv!$A:$A,'VENTA T'!$B$25) -> 224168 | E34: =SUMIFS(inv!$D:$D,inv!$T:$T,'VENTA T'!$B34,inv!$U:$U,'VENTA T'!$E$27,inv!$A:$A,'VENTA T'!$B$25) -> 0 | F34: =SUMIFS(VENTAS!$H:$H,VENTAS!$G:$G,'VENTA T'!$B34,VENTAS!$B:$B,'VENTA T'!$B$25) -> 61413.5 | G34: =C34/$F34 -> 1.237057 | H34: =D34/$F34 -> 3.6501421 | I34: =E34/$F34 -> 0 | J34: =H34+I34 -> 3.6501421 | K34: =IFERROR(C34-F34,0) -> 14558.5
B35: TAT CARTAGENA | C35: =SUMIFS(inv!$D:$D,inv!$T:$T,'VENTA T'!$B35,inv!$U:$U,'VENTA T'!$C$27,inv!$A:$A,'VENTA T'!$B$25) -> 3945 | D35: =SUMIFS(inv!$D:$D,inv!$T:$T,'VENTA T'!$B35,inv!$U:$U,'VENTA T'!$D$27,inv!$A:$A,'VENTA T'!$B$25) -> 39075 | E35: =SUMIFS(inv!$D:$D,inv!$T:$T,'VENTA T'!$B35,inv!$U:$U,'VENTA T'!$E$27,inv!$A:$A,'VENTA T'!$B$25) -> 84480 | F35: =SUMIFS(VENTAS!$H:$H,VENTAS!$G:$G,'VENTA T'!$B35,VENTAS!$B:$B,'VENTA T'!$B$25) -> 2392.5 | G35: =C35/$F35 -> 1.6489028 | H35: =D35/$F35 -> 16.332288 | I35: =E35/$F35 -> 35.310345 | J35: =H35+I35 -> 51.642633 | K35: =IFERROR(C35-F35,0) -> 1552.5
B36: TAT BOGOTA SIBERIA | C36: =SUMIFS(inv!$D:$D,inv!$T:$T,'VENTA T'!$B36,inv!$U:$U,'VENTA T'!$C$27,inv!$A:$A,'VENTA T'!$B$25) -> 49235 | D36: =SUMIFS(inv!$D:$D,inv!$T:$T,'VENTA T'!$B36,inv!$U:$U,'VENTA T'!$D$27,inv!$A:$A,'VENTA T'!$B$25) -> 36475 | E36: =SUMIFS(inv!$D:$D,inv!$T:$T,'VENTA T'!$B36,inv!$U:$U,'VENTA T'!$E$27,inv!$A:$A,'VENTA T'!$B$25) -> 0 | F36: =SUMIFS(VENTAS!$H:$H,VENTAS!$G:$G,'VENTA T'!$B36,VENTAS!$B:$B,'VENTA T'!$B$25) -> 22647.667 | G36: =C36/$F36 -> 2.1739546 | H36: =D36/$F36 -> 1.6105412 | I36: =E36/$F36 -> 0 | J36: =H36+I36 -> 1.6105412 | K36: =IFERROR(C36-F36,0) -> 26587.333
B37: TAT MEDELLIN | C37: =SUMIFS(inv!$D:$D,inv!$T:$T,'VENTA T'!$B37,inv!$U:$U,'VENTA T'!$C$27,inv!$A:$A,'VENTA T'!$B$25) -> 78619 | D37: =SUMIFS(inv!$D:$D,inv!$T:$T,'VENTA T'!$B37,inv!$U:$U,'VENTA T'!$D$27,inv!$A:$A,'VENTA T'!$B$25) -> 133644 | E37: =SUMIFS(inv!$D:$D,inv!$T:$T,'VENTA T'!$B37,inv!$U:$U,'VENTA T'!$E$27,inv!$A:$A,'VENTA T'!$B$25) -> 84480 | F37: =SUMIFS(VENTAS!$H:$H,VENTAS!$G:$G,'VENTA T'!$B37,VENTAS!$B:$B,'VENTA T'!$B$25) -> 53177.5 | G37: =C37/$F37 -> 1.478426 | H37: =D37/$F37 -> 2.5131682 | I37: =E37/$F37 -> 1.5886418 | J37: =H37+I37 -> 4.10181 | K37: =IFERROR(C37-F37,0) -> 25441.5
B38: TAT MONTERIA | C38: =SUMIFS(inv!$D:$D,inv!$T:$T,'VENTA T'!$B38,inv!$U:$U,'VENTA T'!$C$27,inv!$A:$A,'VENTA T'!$B$25) -> 1620 | D38: =SUMIFS(inv!$D:$D,inv!$T:$T,'VENTA T'!$B38,inv!$U:$U,'VENTA T'!$D$27,inv!$A:$A,'VENTA T'!$B$25) -> 17640 | E38: =SUMIFS(inv!$D:$D,inv!$T:$T,'VENTA T'!$B38,inv!$U:$U,'VENTA T'!$E$27,inv!$A:$A,'VENTA T'!$B$25) -> 0 | F38: =SUMIFS(VENTAS!$H:$H,VENTAS!$G:$G,'VENTA T'!$B38,VENTAS!$B:$B,'VENTA T'!$B$25)+F40 -> 17173 | G38: =C38/$F38 -> 0.094334129 | H38: =D38/$F38 -> 1.0271939 | I38: =E38/$F38 -> 0 | J38: =H38+I38 -> 1.0271939 | K38: =IFERROR(C38-F38,0) -> -15553
B39: TAT SANTA MARTA | C39: =SUMIFS(inv!$D:$D,inv!$T:$T,'VENTA T'!$B39,inv!$U:$U,'VENTA T'!$C$27,inv!$A:$A,'VENTA T'!$B$25) -> 21858 | D39: =SUMIFS(inv!$D:$D,inv!$T:$T,'VENTA T'!$B39,inv!$U:$U,'VENTA T'!$D$27,inv!$A:$A,'VENTA T'!$B$25) -> 10242 | E39: =SUMIFS(inv!$D:$D,inv!$T:$T,'VENTA T'!$B39,inv!$U:$U,'VENTA T'!$E$27,inv!$A:$A,'VENTA T'!$B$25) -> 0 | F39: =SUMIFS(VENTAS!$H:$H,VENTAS!$G:$G,'VENTA T'!$B39,VENTAS!$B:$B,'VENTA T'!$B$25) -> 15672.5 | G39: =C39/$F39 -> 1.3946722 | H39: =D39/$F39 -> 0.65350136 | I39: =E39/$F39 -> 0 | J39: =H39+I39 -> 0.65350136 | K39: =IFERROR(C39-F39,0) -> 6185.5
B40: TAT SINCELEJO | C40: =SUMIFS(inv!$D:$D,inv!$T:$T,'VENTA T'!$B40,inv!$U:$U,'VENTA T'!$C$27,inv!$A:$A,'VENTA T'!$B$25) -> 2008 | D40: =SUMIFS(inv!$D:$D,inv!$T:$T,'VENTA T'!$B40,inv!$U:$U,'VENTA T'!$D$27,inv!$A:$A,'VENTA T'!$B$25) -> 24120 | E40: =SUMIFS(inv!$D:$D,inv!$T:$T,'VENTA T'!$B40,inv!$U:$U,'VENTA T'!$E$27,inv!$A:$A,'VENTA T'!$B$25) -> 0 | F40: =SUMIFS(VENTAS!$H:$H,VENTAS!$G:$G,'VENTA T'!$B40,VENTAS!$B:$B,'VENTA T'!$B$25) -> 13892.5 | G40: =C40/$F40 -> 0.14453842 | H40: =D40/$F40 -> 1.7361886 | I40: =E40/$F40 -> 0 | J40: =H40+I40 -> 1.7361886 | K40: =IFERROR(C40-F40,0) -> -11884.5
B41: TAT VILLAVICENCIO | C41: =SUMIFS(inv!$D:$D,inv!$T:$T,'VENTA T'!$B41,inv!$U:$U,'VENTA T'!$C$27,inv!$A:$A,'VENTA T'!$B$25) -> 22420 | D41: =SUMIFS(inv!$D:$D,inv!$T:$T,'VENTA T'!$B41,inv!$U:$U,'VENTA T'!$D$27,inv!$A:$A,'VENTA T'!$B$25) -> 13754 | E41: =SUMIFS(inv!$D:$D,inv!$T:$T,'VENTA T'!$B41,inv!$U:$U,'VENTA T'!$E$27,inv!$A:$A,'VENTA T'!$B$25) -> 69120 | F41: =SUMIFS(VENTAS!$H:$H,VENTAS!$G:$G,'VENTA T'!$B41,VENTAS!$B:$B,'VENTA T'!$B$25) -> 19625.5 | G41: =C41/$F41 -> 1.1423913 | H41: =D41/$F41 -> 0.70082291 | I41: =E41/$F41 -> 3.5219485 | J41: =H41+I41 -> 4.2227714 | K41: =IFERROR(C41-F41,0) -> 2794.5
C42: =SUM(C28:C41) -> 922086 | D42: =SUM(D28:D41) -> 1255540 | E42: =SUM(E28:E41) -> 805440 | F42: =SUM(F28:F41) -> 773257.5
...

Sheet CEDIS
A1: VOLVER
C4: CEDI | D4: COD | E4: NOMBRE | F4: INVENTARIO TOTAL | G4: PROMEDIO VENTAS | H4: PROMEDIO PROYECCIÓN | I4: DÍAS INVENTARIO | J4: COBERTURA. | K4: INV. VEHICULOS | L4: DIAS INV VEHICULOS | M4: INV. TRANSITO | N4: DÍAS INV . TRANSITO | O4: INV. BODEGA | P4: DIAS INV. BODEGA
C5: TAT BARRANQUILLA | D5: 79201 | E5: DESECHO HUEVO CASCARA | F5: 2757 | G5: 0 | H5: 0 | I5: 0 | J5: 0 | K5: 365 | L5: 0 | M5: 0 | N5: 0 | O5: 2392 | P5: 0
C6: TAT BARRANQUILLA | D6: 13503 | E6: HUEVO B X 30 BAND GRIS AMARRADO ALAT | F6: 360 | G6: 0 | H6: 0 | I6: 0 | J6: 0 | K6: 360 | L6: 0 | M6: 0 | N6: 0 | O6: 0 | P6: 0
C7: TAT BARRANQUILLA | D7: 79101 | E7: HUEVO ROTO | F7: 140 | G7: 0 | H7: 0 | I7: 0 | J7: 0 | K7: 0 | L7: 0 | M7: 0 | N7: 0 | O7: 140 | P7: 0
C8: TAT BARRANQUILLA | D8: 10501 | E8: HUEVO B X30 CARTON GRIS | F8: 80 | G8: 0 | H8: 0 | I8: 0 | J8: 0 | K8: 80 | L8: 0 | M8: 0 | N8: 0 | O8: 0 | P8: 0
C9: TAT BARRANQUILLA | D9: 13480 | E9: HUEVO A X 30 BANDEJA GRIS ALAT CAJA X 360 | F9: 0 | G9: 0 | H9: 0 | I9: 0 | J9: 0 | K9: 0 | L9: 0 | M9: 0 | N9: 0 | O9: 0 | P9: 0
C10: TAT BARRANQUILLA | D10: 72101 | E10: SUCIO ROJO PEQUEÑO | F10: 0 | G10: 0 | H10: 0 | I10: 0 | J10: 0 | K10: 0 | L10: 0 | M10: 0 | N10: 0 | O10: 0 | P10: 0
C11: TAT BARRANQUILLA | D11: 76501 | E11: REVOLTURA COMERCIAL PEQUEÑA | F11: 0 | G11: 0 | H11: 0 | I11: 0 | J11: 0 | K11: 0 | L11: 0 | M11: 0 | N11: 0 | O11: 0 | P11: 0
C12: TAT BARRANQUILLA | D12: 10104 | E12: HUEVO YUMBO X20 FS CARTON VERDE | F12: 0 | G12: 0 | H12: 0 | I12: 0 | J12: 0 | K12: 0 | L12: 0 | M12: 0 | N12: 0 | O12: 0 | P12: 0
C13: TAT BARRANQUILLA | D13: 106 | E13: HUEVO C. ROJO | F13: 0 | G13: 0 | H13: 0 | I13: 0 | J13: 0 | K13: 0 | L13: 0 | M13: 0 | N13: 0 | O13: 0 | P13: 0
C14: TAT BARRANQUILLA | D14: 10201 | E14: HUEVO AAA X30 CARTON GRIS | F14: 0 | G14: 0 | H14: 0 | I14: 0 | J14: 0 | K14: 0 | L14: 0 | M14: 0 | N14: 0 | O14: 0 | P14: 0
C15: TAT BARRANQUILLA | D15: 52378 | E15: HUEVO AA X 15 PAGUE 12 PET CAJA POR 360 | F15: 0 | G15: 0 | H15: 0 | I15: 0 | J15: 0 | K15: 0 | L15: 0 | M15: 0 | N15: 0 | O15: 0 | P15: 0
C16: TAT BARRANQUILLA | D16: 10202 | E16: HUEVO AAA X30 CARTON VERDE | F16: 0 | G16: 0 | H16: 0 | I16: 0 | J16: 0 | K16: 0 | L16: 0 | M16: 0 | N16: 0 | O16: 0 | P16: 0
... C2138: TAT BOGOTA MONTEVIDEO | D2138: 13359 | E2138: HUEVO AA X 300 BANDEJA GRIS ALAT CAJA AMARRADO | F2138: 0 | G2138: 0 | H2138: 0 | I2138: 0 | J2138: 0 | K2138: 0 | L2138: 0 | M2138: 0 | N2138: 0 | O2138: 0 | P2138: 0
C2139: Total general | F2139: 1461981 | G2139: 8616 | H2139: 19740 | I2139: 1.9242424 | J2139: 0 | K2139: 19860 | L2139: 0.69318182 | M2139: 707194 | N2139: 0 | O2139: 734927 | P2139: 1.2310606

Sheet PLANTAS
A1: VOLVER
E5: Etiquetas de fila | F5: NOMBRE | G5: INVENTARIO.
E6: SANTANDER
E7: 2110402 | F7: HUEVO M X 30 CARTON VERDE CANASTA | G7: 459727
E8: 2010501 | F8: HUEVO B X30 CARTON GRIS CANASTA | G8: 288079
E9: 10601 | F9: HUEVO CX30 CARTON GRIS | G9: 150622
E10: 2110302 | F10: HUEVO L X 30 CARTON VERDE CANASTA | G10: 90736
E11: 10501 | F11: HUEVO B X30 CARTON GRIS | G11: 38288
E12: 112379 | F12: HUEVO L X 30 PET CAJA X 300 | G12: 37200
E13: 79111 | F13: HUEVO ROTO ZF- SANTANDER | G13: 31995
E14: 75301 | F14: HUEVO AA X 30 CARTON GRIS LZ | G14: 30030
E15: 2110202 | F15: HUEVO XL X 30 CARTON VERDE CANASTA | G15: 28939
E16: 75401 | F16: HUEVO A X 30 CARTON GRIS LZ | G16: 16080
E17: 13459 | F17: HUEVO A X 300 BANDEJA GRIS ALAT CAJA AMARRADO | G17: 15600
E18: 2010102 | F18: HUEVO YUMBO X20 CARTON VERDE CANASTA | G18: 14825
... E21: 112268 | F21: HUEVO XL X 15 PET CAJA X 300 | G21: 4200
F22: HUEVO XL X 15 PET CAJA X 300. | G22: 4200
E23: 110303 | F23: HUEVO L X30 CARTON VERDE AMARRADO | G23: 8100
E24: 2152388 | F24: HUEVO L X 15 PAGUE 14 PET EN CANASTA. | G24: 7200
E25: 152384 | F25: HUEVO L X 15 PAGUE 14 PET CAJA X 300. | G25: 5100
E26: 13403 | F26: HUEVO A X 30 BAND GRIS AMARRADO ALAT | G26: 5040
E27: 10401 | F27: HUEVO A X30 CARTON GRIS | G27: 5040
E28: 75201 | F28: HUEVO AAA X 30 CARTON GRIS LZ | G28: 4530
E29: 75501 | F29: HUEVO B X 30 CARTON GRIS LZ | G29: 2580
E30: 72001 | F30: HUEVO SUCIO DE JAULA | G30: 1714
E31: 76601 | F31: REVOLTURA COMERCIAL MEDIANA | G31: 619
E32: 72003 | F32: HUEVO SUCIO ZF MARCADO | G32: 476
E33: 72005 | F33: HUEVO SUCIO SIN MARCA X30 BANDEJA GRIS L | G33: 0
E34: 2110410 | F34: HUEVO M X30 CARTON VERDE AMARRADO CON BANDEJA CANASTA | G34: 0
... E187: 10318 | F187: HUEVO AAX30 CARTÓN VERDE MICROBIOLOGICO CON ETIQUETA | G187: 0
E188: Total SANTANDER | G188: 1267968
E189: CALOTO
E190: 2110202 | F190: HUEVO XL X 30 CARTON VERDE CANASTA | G190: 620029
E191: 2010301 | F191: HUEVO AA X30 CARTON GRIS CANASTA | G191: 521124
E192: 73001 | F192: HUEVO PICADO ROJO | G192: 236592
E193: 112268 | F193: HUEVO XL X 15 PET CAJA X 300 | G193: 84000
F194: HUEVO XL X 15 PET CAJA X 300. | G194: 84000
E195: 2110302 | F195: HUEVO L X 30 CARTON VERDE CANASTA | G195: 145099
E196: 72003 | F196: HUEVO SUCIO ZF MARCADO | G196: 118294
E197: 75201 | F197: HUEVO AAA X 30 CARTON GRIS LZ | G197: 81502
...

Sheet CONVERSION DATOS
A1: DESTINO | B1: id_bodega | C1: DESTINO | D1: GRUPO
A2: KIKES - EGIPTO | B2: ALKA | C2: ALKA1 | D2: PLANTA CLASIFICACION
A3: KIKES2 - EGIPTO | B3: ALKA2 | C3: ALKA2 | D3: PLANTA CLASIFICACION
A4: BODEGA INTEGRADO JP | B4: AT1 | C4: INTEGRADO JP | D4: PLANTA CLASIFICACION
A5: BELLAVISTA | B5: BE | C5: BELLAVISTA | D5: PLANTA CLASIFICACION
A6: BARRANQUILLA CLASIFICACION | B6: BQ | C6: TAT CE BARRANQUILLA | D6: BODEGA
A7: CLASIFICADORA LANZA | B7: CLKI | C7: LANZA | D7: HUEVO SIN CLASIFICAR
A8: ELABORACION DE PRODUCTOS - ALKA | B8: EPALKA | C8: ALKA1 | D8: PLANTA CLASIFICACION
A9: ELABORACION DE PRODUCTO BARRANQUILLA CLASIFICACION | B9: EPBQ | C9: TAT CE BARRANQUILLA | D9: BODEGA
A10: ELABORACION DE PRODUCTOS - ALKA2 | B10: EPALKA2 | C10: ALKA2 | D10: PLANTA CLASIFICACION
A11: ELABORACION DE PRODUCTOS - KI | B11: EPKI | C11: LANZA | D11: PLANTA CLASIFICACION
A12: ELABORACION DE PRODUCTOS - PALMAS | B12: EPPALM | C12: PALMAS | D12: PLANTA CLASIFICACION
... A273: TATBOGOTA SIBERIA ROTURAS | B273: H5900 | C273: TAT BOGOTA SIBERIA | D273: OTROS
B274: Barranquilla | C274: TAT BARRANQUILLA
B275: BOGOTA | C275: TAT BOGOTA MONTEVIDEO
A276: BOGOTA MONTEVIDEO | B276: BOGOTA | C276: TAT BOGOTA MONTEVIDEO
B277: Alka1 | C277: ALKA1
B278: BOGOTA | C278: TAT BOGOTA MONTEVIDEO
B279: Bucaramanga | C279: TAT BUCARAMANGA
B280: Alka2 | C280: ALKA2
B281: Cali | C281: TAT CALI
B282: Cartagena | C282: TAT CARTAGENA | D282: OTROS
B283: BE | C283: BE
B284: Cucuta | C284: TAT CUCUTA
B285: Medellin | C285: TAT MEDELLIN
B286: Monteria | C286: TAT MONTERIA
B287: Lanza | C287: LANZA
B288: Pasto | C288: TAT PASTO
B289: Popayan | C289: TAT POPAYAN
B290: Santa Marta | C290: TAT SANTA MARTA | D290: OTROS
B291: Palmas | C291: PALMAS
B292: Valledupar | C292: TAT VALLEDUPAR
B293: BOGOTA | C293: TAT BOGOTA MONTEVIDEO
A294: TAT H3050 - AUTOSERVICIOS | B294: H3050 | C294: TAT MEDELLIN | D294: VEHICULOS
A295: TAT CARTAGENA H4140 - ESPECIAL | B295: H4140 | C295: TAT CARTAGENA | D295: VEHICULOS
A296: TAT SANTAMARTA - INVENTARIO TRANSITO | B296: VT42 | C296: TAT SANTA MARTA | D296: TRANSITO
A297: TAT PASTO - INVENTARIO TRANSITO | B297: VT6 | C297: TAT PASTO | D297: TRANSITO
A298: BODEGA BELLAVISTA - INVENTARIO TRANSITO | B298: VTBE | C298: BELLAVISTA | D298: PLANTA CLASIFICACION
A299: BODEGA DE CONSERVACION Y DESPACHO PUERTO TEJADA | B299: GC25 | C299: 0 | D299: BODEGA
A300: TAT CALI H2025 | B300: H2025 | C300: TAT CALI | D300: VEHICULOS
...

Sheet Hoja1
A1: id_bodega | C1: DESTINO | D1: id_bodega | E1: DESTINO | F1: GRUPO
A2: 4 | C2: KIKES - EGIPTO | D2: ALKA | E2: ALKA1 | F2: PLANTA CLASIFICACION
A3: 7 | C3: KIKES2 - EGIPTO | D3: ALKA2 | E3: ALKA2 | F3: PLANTA CLASIFICACION
A4: AL04 | C4: BODEGA INTEGRADO JP | D4: AT1 | E4: INTEGRADO JP | F4: PLANTA CLASIFICACION
A5: AL12 | C5: BELLAVISTA | D5: BE | E5: BELLAVISTA | F5: PLANTA CLASIFICACION
A6: ALEM | C6: BARRANQUILLA CLASIFICACION | D6: BQ | E6: TAT CE BARRANQUILLA | F6: BODEGA
A7: EC | C7: CLASIFICADORA LANZA | D7: CLKI | E7: LANZA | F7: HUEVO SIN CLASIFICAR
A8: ECCA | C8: ELABORACION DE PRODUCTOS - ALKA | D8: EPALKA | E8: ALKA1 | F8: PLANTA CLASIFICACION
A9: EMBQ | C9: ELABORACION DE PRODUCTO BARRANQUILLA CLASIFICACION | D9: EPBQ | E9: TAT CE BARRANQUILLA | F9: BODEGA
A10: EQ | C10: ELABORACION DE PRODUCTOS - ALKA2 | D10: EPALKA2 | E10: ALKA2 | F10: PLANTA CLASIFICACION
A11: EQZF | C11: ELABORACION DE PRODUCTOS - KI | D11: EPKI | E11: LANZA | F11: PLANTA CLASIFICACION
A12: GA04 | C12: ELABORACION DE PRODUCTOS - PALMAS | D12: EPPALM | E12: PALMAS | F12: PLANTA CLASIFICACION
A13: GC02-05 | C13: ELABORACION DE PRODUCTOS - BELLAVISTA | D13: EPBE | E13: BELLAVISTA | F13: PLANTA CLASIFICACION
A14: GP25-1 | C14: TAT BUCARAMANGA - FOOD SERVICE | D14: FS1 | E14: TAT BUCARAMANGA | F14: VEHICULOS
A15: GV25 | C15: TAT MEDELLIN - FOOD SERVICE | D15: FS3 | E15: TAT MEDELLIN | F15: VEHICULOS
... A24: VTPULV | C24: TAT BUCARAMANGA H1005 | D24: H1005 | E24: TAT BUCARAMANGA | F24: VEHICULOS
A25: 1 | C25: TAT BUCARAMANGA H1006 | D25: H1006 | E25: TAT BUCARAMANGA | F25: VEHICULOS
A26: 01BE | C26: TAT BUCARAMANGA H1007 | D26: H1007 | E26: TAT BUCARAMANGA | F26: VEHICULOS
A27: 01IN | C27: TAT BUCARAMANGA H1008 | D27: H1008 | E27: TAT BUCARAMANGA | F27: VEHICULOS
A28: 01LZ | C28: TAT BUCARAMANGA H1009 | D28: H1009 | E28: TAT BUCARAMANGA | F28: VEHICULOS
A29: 01PA | C29: TAT BUCARAMANGA H1010 | D29: H1010 | E29: TAT BUCARAMANGA | F29: VEHICULOS
A30: 02BE | C30: TAT BUCARAMANGA H1011 | D30: H1011 | E30: TAT BUCARAMANGA | F30: VEHICULOS
A31: 03BE | C31: TAT BUCARAMANGA H1012 | D31: H1012 | E31: TAT BUCARAMANGA | F31: VEHICULOS
A32: 03BEPA | C32: TAT BUCARAMANGA H1013 | D32: H1013 | E32: TAT BUCARAMANGA | F32: VEHICULOS
A33: 11 | C33: TAT BUCARAMANGA H1014 | D33: H1014 | E33: TAT BUCARAMANGA | F33: VEHICULOS
A34: AL01 | C34: TAT BUCARAMANGA H1015 | D34: H1015 | E34: TAT BUCARAMANGA | F34: VEHICULOS
A35: AL02 | C35: TAT BUCARAMANGA H1016 | D35: H1016 | E35: TAT BUCARAMANGA | F35: VEHICULOS
A36: AL07 | C36: TAT BUCARAMANGA H1017 | D36: H1017 | E36: TAT BUCARAMANGA | F36: VEHICULOS
A37: AL09 | C37: TAT H1050 - AUTOSERVICIOS | D37: H1050 | E37: TAT BUCARAMANGA | F37: VEHICULOS
A38: AL09MS | C38: TAT CALI H2001 | D38: H2001 | E38: TAT CALI | F38: VEHICULOS
A39: AL11 | C39: TAT CALI H2002 | D39: H2002 | E39: TAT CALI | F39: VEHICULOS
A40: AL12PA | C40: TAT CALI H2003 | D40: H2003 | E40: TAT CALI | F40: VEHICULOS
A41: ALF01 | C41: TAT CALI H2005 | D41: H2005 | E41: TAT CALI | F41: VEHICULOS
A42: GA01 | C42: TAT CALI H2006 | D42: H2006 | E42: TAT CALI | F42: VEHICULOS
A43: GA01PA | C43: TAT CALI H2008 | D43: H2008 | E43: TAT CALI | F43: VEHICULOS
A44: GA07 | C44: TAT CALI H2009 | D44: H2009 | E44: TAT CALI | F44: VEHICULOS
A45: PL01 | C45: TAT CALI H2010 | D45: H2010 | E45: TAT CALI | F45: VEHICULOS
... A56: RTME | C56: TAT POPAYAN H2301 | D56: H2301 | E56: TAT POPAYAN | F56: VEHICULOS
C57: TAT POPAYAN H2302 | D57: H2302 | E57: TAT POPAYAN | F57: VEHICULOS
C58: TAT POPAYAN H2303 | D58: H2303 | E58: TAT POPAYAN | F58: VEHICULOS
...

Sheet DT HUEVO
A1: CODIGO | B1: NOMBRE | C1: TIPO | D1: TIPO2 | E1: TIPO3 | F1: CANAL | H1: PLANTA | I1: ZONA | J1: P | K1: ZONA
A2: 90 | B2: HUEVO ROJO SIN CLASIFICAR GRANJAS | C2: HUEVO SIN CLASIFICAR | D2: HUEVO SIN CLASIFICAR | E2: HUEVO SIN CLASIFICAR | F2: SIN CL | H2: ALKA1 | I2: - | J2: CALOTO | K2: PLANTAS
A3: 91 | B3: HUEVO ROJO SIN CLASIFICAR JAULA EGIPTO PROD1 | C3: HUEVO SIN CLASIFICAR | D3: HUEVO SIN CLASIFICAR | E3: HUEVO SIN CLASIFICAR | F3: SIN CL | H3: ALKA2 | I3: - | J3: CALOTO | K3: PLANTAS
A4: 92 | B4: HUEVO ROJO SIN CLASIFICAR BELLAVISTA | C4: HUEVO SIN CLASIFICAR | D4: HUEVO SIN CLASIFICAR | E4: HUEVO SIN CLASIFICAR | F4: SIN CL | H4: PALMAS | I4: - | J4: CALOTO | K4: PLANTAS
A5: 93 | B5: HUEVO ROJO SIN CLASIFICAR JAULA EGIPTO PROD2 | C5: HUEVO SIN CLASIFICAR | D5: HUEVO SIN CLASIFICAR | E5: HUEVO SIN CLASIFICAR | F5: SIN CL | H5: BELLAVISTA | I5: - | J5: SANTANDER | K5: PLANTAS
A6: 94 | B6: HUEVO ROJO SIN CLASIFICAR DE LA GRANJA PALMAS | C6: HUEVO SIN CLASIFICAR | D6: HUEVO SIN CLASIFICAR | E6: HUEVO SIN CLASIFICAR | F6: SIN CL | H6: LANZA | I6: - | J6: SANTANDER | K6: PLANTAS
A7: 100 | B7: HUEVO SIN CLASIFICAR ROJO | C7: HUEVO SIN CLASIFICAR | D7: HUEVO SIN CLASIFICAR | E7: HUEVO SIN CLASIFICAR | F7: SIN CL | H7: EXPENDIO | I7: - | J7: - | K7: -
A8: 101 | B8: HUEVO YUMBO ROJO | C8: YUMBO | D8: GRIS SUELTO | F8: MAY | H8: TAT BUCARAMANGA | I8: COSTA | J8: SANTANDER | K8: CENTRO ORIENTE
A9: 102 | B9: HUEVO A.A.A. ROJO | C9: AAA | D9: GRIS SUELTO | F9: MAY | H9: TAT CALI | I9: OCCIDENTE | J9: CALOTO | K9: OCCIDENTE
A10: 103 | B10: HUEVO A.A. ROJO | C10: AA | D10: GRIS SUELTO | F10: MAY | H10: TAT MEDELLIN | I10: OCCIDENTE | J10: CALOTO | K10: OCCIDENTE
A11: 104 | B11: HUEVO A. ROJO | C11: A | D11: GRIS SUELTO | F11: MAY | H11: TAT BARRANQUILLA | I11: COSTA | J11: CALOTO | K11: COSTA ORIENTE
A12: 105 | B12: HUEVO B. ROJO | C12: B | D12: GRIS SUELTO | F12: MAY | H12: TAT CARTAGENA | I12: COSTA | J12: CALOTO | K12: COSTA ORIENTE
A13: 106 | B13: HUEVO C. ROJO | C13: C | D13: SEGUNDA | F13: SEGUNDA | H13: TAT BOGOTA MONTEVIDEO | I13: CENTRO ORIENTE | J13: SANTANDER | K13: CENTRO ORIENTE
A14: 130 | B14: HUEVO PICADO ROJO | C14: SEGUNDA | D14: SEGUNDA | E14: PICADO | F14: SEGUNDA | H14: TAT POPAYAN | I14: OCCIDENTE | J14: CALOTO | K14: OCCIDENTE
A15: 300 | B15: HUEVO SIN CLASIFICAR COMERCIAL | C15: HUEVO SIN CLASIFICAR | D15: HUEVO SIN CLASIFICAR | E15: HUEVO SIN CLASIFICAR | F15: SIN CL | H15: TAT PEREIRA | I15: OCCIDENTE | J15: CALOTO | K15: OCCIDENTE
A16: 901 | B16: HUEVO ROTO | C16: HUEVO SIN CLASIFICAR | D16: HUEVO SIN CLASIFICAR | E16: HUEVO SIN CLASIFICAR | F16: SIN CL | H16: TAT STA MARTA | I16: COSTA | J16: SANTANDER | K16: COSTA ORIENTE
A17: 902 | B17: DESECHOS | C17: SEGUNDA | D17: SEGUNDA | F17: SEGUNDA | H17: TAT VALLEDUPAR | I17: COSTA | J17: SANTANDER | K17: COSTA ORIENTE
A18: 1042 | B18: HUEVO A2 ROJO | C18: A | H18: TAT BOGOTA SIBERIA | I18: CENTRO ORIENTE | J18: CALOTO | K18: CENTRO ORIENTE
A19: 10101 | B19: HUEVO YUMBO X20 CARTON GRIS | C19: YUMBO | D19: GRIS SUELTO | F19: MAY | H19: TAT VILLAVICENCIO | I19: CENTRO ORIENTE | J19: SANTANDER | K19: CENTRO ORIENTE
A20: 10102 | B20: HUEVO YUMBO X20 CARTON VERDE | C20: YUMBO | D20: VERDE | F20: TAT | H20: TAT PASTO | I20: OCCIDENTE | J20: CALOTO | K20: OCCIDENTE
A21: 10103 | B21: HUEVO YUMBO X20 CARTON VERDE AMARRADO | C21: YUMBO | D21: EMPACADOS | F21: AU/FS/GS | H21: TAT CUCUTA | I21: COSTA | J21: SANTANDER | K21: CENTRO ORIENTE
A22: 10104 | B22: HUEVO YUMBO X20 FS CARTON VERDE | C22: YUMBO | D22: EMPACADOS | H22: TAT MONTERIA | I22: COSTA | J22: SANTANDER | K22: COSTA ORIENTE
A23: 10106 | B23: HUEVO YUMBO X 20 BANDEJA VERDE CON ETIQUETA | C23: YUMBO | D23: VERDE | F23: TAT | H23: TAT BOGOTA SIBERIA | I23: CENTRO ORIENTE | J23: CALOTO | K23: CENTRO ORIENTE
A24: 10201 | B24: HUEVO AAA X30 CARTON GRIS | C24: AAA | D24: GRIS SUELTO | F24: MAY | H24: EXPENDIO - EGIPTO | I24: - | J24: - | K24: -
A25: 10202 | B25: HUEVO AAA X30 CARTON VERDE | C25: AAA | D25: VERDE | F25: TAT | H25: CENTRO DE EMPAQUES | I25: COSTA | J25: - | K25: COSTA ORIENTE
A26: 10203 | B26: HUEVO AAA X30 CARTON VERDE AMARRADO | C26: AAA | D26: EMPACADOS | H26: HUEVO SIN CLASIFICAR | I26: - | J26: - | K26: -
A27: 10204 | B27: HUEVO AAA X30 FS CARTON VERDE | C27: AAA | D27: FS | H27: BODEGA MAYORISTA | I27: NA | J27: NA | K27: NA
A28: 10205 | B28: HUEVO AAA X30 FS CARTON VERDE AMARRADO | C28: AAA | D28: FS | H28: FOODSERVICE NACIONAL | I28: NA | J28: NA | K28: NA
A29: 10213 | B29: HUEVO AAA X 45 BANDEJA VERDE AMARRADO | C29: AAA | D29: VERDE | F29: TAT | H29: TAT BOGOTA MONTEVIDEO | I29: CENTRO ORIENTE | J29: SANTANDER | K29: CENTRO ORIENTE
A30: 10216 | B30: HUEVO AAA X 30 CARTON VERDE CON ETIQUETA | C30: AAA | D30: ETIQUETA | F30: AU/FS/GS | H30: BODEGA ZF | I30: ZF | J30: ZF | K30: ZF
A31: 10268 | B31: HUEVO AAA X 288 BAND GRIS CAJA DOCENERA EXTRA | C31: AAA | D31: EMPACADOS | F31: HD | H31: INTEGRADO JP | I31: - | J31: - | K31: -
A32: 10269 | B32: HUEVO AAA X 300 BANDEJA VERDE CAJA AMARRADO | C32: AAA | D32: EMPACADOS | H32: BODEGA GAITAN | I32: - | J32: SANTANDER
A33: 10278 | B33: HUEVO AAA X 30 BANDEJA VERDE CAJA X 240 AMARRADO | C33: AAA | D33: EMPACADOS | H33: TAT SANTA MARTA | I33: COSTA | J33: SANTANDER | K33: COSTA ORIENTE
A34: 10289 | B34: HUEVO AAA X 360 FS CARTON VERDE CAJA | C34: AAA | D34: EMPACADOS | H34: GRANJAS DE PISO | I34: - | J34: - | K34: -
A35: 10301 | B35: HUEVO AA X30 CARTON GRIS | C35: AA | D35: GRIS SUELTO | F35: MAY | H35: TAT Barranquilla | I35: COSTA | J35: CALOTO | K35: COSTA ORIENTE
A36: 10302 | B36: HUEVO AA X30 CARTON VERDE | C36: AA | D36: VERDE | F36: TAT | H36: TAT BOGOTA MONTEVIDEO | I36: CENTRO ORIENTE | J36: SANTANDER | K36: CENTRO ORIENTE
A37: 10303 | B37: HUEVO AA X30 CARTON VERDE AMARRADO | C37: AA | D37: EMPACADOS | H37: TAT Bogota Montevideo | I37: CENTRO ORIENTE | J37: CALOTO | K37: CENTRO ORIENTE
A38: 10304 | B38: HUEVO AA X30 FS CARTON VERDE | C38: AA | D38: FS | H38: Alka1 | I38: - | J38: CALOTO | K38: PLANTAS
A39: 10305 | B39: HUEVO AA X30 FS CARTON VERDE AMARRADO | C39: AA | D39: FS | H39: TAT BOGOTA SIBERIA | I39: CENTRO ORIENTE | J39: CALOTO | K39: CENTRO ORIENTE
A40: 10306 | B40: HUEVO AA X12 CARTON VERDE | C40: AA | D40: VERDE | F40: TAT | H40: TAT Bucaramanga | I40: CENTRO ORIENTE | J40: SANTANDER | K40: CENTRO ORIENTE
...

Sheet Hoja2
A1: id_bodega
A24: EC
A25: ECCA
A26: EMBQ
A33: GC02
A34: GC02-05
A35: GP25-1
A36: GV25
A45: SV01
A46: SV02
A47: SV1CAL
A48: VT01BE

Sheet inv
A1: articulo | B1: descripcion_articulo | C1: id_unidad | D1: cantidad | E1: por_dsto | F1: ind_iva_venta | G1: iva_ventas | H1: por_iva | I1: precio_unitario | J1: codigo_linea | K1: descripcion_linea | L1: costo_promedio | M1: fecha | N1: codigo_plu | O1: descripcion | P1: cod_barras1 | Q1: id_bodega | R1: num_piezas | S1: id_item_bodega | T1: id_item_bodega2 | U1: GRUPO | V1: TIPO DE HUEVO | W1: TIPO DE HUEVO 2 | X1: ZONA | Y1: P | Z1: MAY | AA1: GRUPO 2 | AB1: CANAL
A2: 10601 | B2: HUEVO C X30 CARTON GRIS | C2: UN | D2: 9212 | E2: 0 | F2: S | G2: IV82 | H2: 0 | I2: 400 | J2: HU | K2: HUEVO COMERCIAL | L2: 130.24 | M2: 46307 | N2: 10601 | O2: KIKES - EGIPTO | P2: 10601 | Q2: ALKA | R2: 0 | T2: =+VLOOKUP(Tabla1[[#This Row],[id_bodega]],'CONVERSION DATOS'!B:D,2,0) -> ALKA1 | U2: =+VLOOKUP(Q2,'CONVERSION DATOS'!B:D,3,0) -> PLANTA CLASIFICACION | V2: =+VLOOKUP($A$1:$A$20894,'DT HUEVO'!$A:$E,3,0) -> C | W2: =+VLOOKUP($A$1:$A$20734,'DT HUEVO'!$A:$E,4,0) -> GRIS SUELTO | X2: =+VLOOKUP(T$1:T$20894,'DT HUEVO'!$H:$K,2,0) -> - | Y2: =+VLOOKUP(T$1:T$20894,'DT HUEVO'!$H:$K,3,0) -> CALOTO | Z2: =+VLOOKUP(A$1:A$20894,'DT HUEVO'!$A:$E,5,0) -> 0 | AA2: =IF(Tabla1[[#This Row],[GRUPO]]="PLANTA CLASIFICACION","BODEGA",IF(Tabla1[[#This Row],[GRUPO]]="BODEGA","BODEGA",Tabla1[[#This Row],[GRUPO]])) -> BODEGA | AB2: =VLOOKUP(Tabla1[[#This Row],[articulo]],'DT HUEVO'!$A:$F,6,0) -> MAY
